Workbook

Sheet WORKLOAD_TEAMS_OLD1
A1: PRIORYTET | B1: DATE | C1: DATE | D1: TOTALS | E1: =TEXT(DATE(2024,1,1)+(E2-1)*7-WEEKDAY(DATE(2024,1,1),2)+1,"dd.mm")&"-"&TEXT(DATE(2024,1,1)+(E2-1)*7-WEEKDAY(DATE(2024,1,1),2)+7,"dd.mm") -> 11.03-17.03 | F1: =TEXT(DATE(2024,1,1)+(F2-1)*7-WEEKDAY(DATE(2024,1,1),2)+1,"dd.mm")&"-"&TEXT(DATE(2024,1,1)+(F2-1)*7-WEEKDAY(DATE(2024,1,1),2)+7,"dd.mm") -> 18.03-24.03 | G1: =TEXT(DATE(2024,1,1)+(G2-1)*7-WEEKDAY(DATE(2024,1,1),2)+1,"dd.mm")&"-"&TEXT(DATE(2024,1,1)+(G2-1)*7-WEEKDAY(DATE(2024,1,1),2)+7,"dd.mm") -> 25.03-31.03 | H1: =TEXT(DATE(2024,1,1)+(H2-1)*7-WEEKDAY(DATE(2024,1,1),2)+1,"dd.mm")&"-"&TEXT(DATE(2024,1,1)+(H2-1)*7-WEEKDAY(DATE(2024,1,1),2)+7,"dd.mm") -> 01.04-07.04 | I1: =TEXT(DATE(2024,1,1)+(I2-1)*7-WEEKDAY(DATE(2024,1,1),2)+1,"dd.mm")&"-"&TEXT(DATE(2024,1,1)+(I2-1)*7-WEEKDAY(DATE(2024,1,1),2)+7,"dd.mm") -> 08.04-14.04 | J1: =TEXT(DATE(2024,1,1)+(J2-1)*7-WEEKDAY(DATE(2024,1,1),2)+1,"dd.mm")&"-"&TEXT(DATE(2024,1,1)+(J2-1)*7-WEEKDAY(DATE(2024,1,1),2)+7,"dd.mm") -> 15.04-21.04 | K1: =TEXT(DATE(2024,1,1)+(K2-1)*7-WEEKDAY(DATE(2024,1,1),2)+1,"dd.mm")&"-"&TEXT(DATE(2024,1,1)+(K2-1)*7-WEEKDAY(DATE(2024,1,1),2)+7,"dd.mm") -> 22.04-28.04 | L1: =TEXT(DATE(2024,1,1)+(L2-1)*7-WEEKDAY(DATE(2024,1,1),2)+1,"dd.mm")&"-"&TEXT(DATE(2024,1,1)+(L2-1)*7-WEEKDAY(DATE(2024,1,1),2)+7,"dd.mm") -> 29.04-05.05 | ... AT1: =TEXT(DATE(2024,1,1)+(AT2-1)*7-WEEKDAY(DATE(2024,1,1),2)+1,"dd.mm")&"-"&TEXT(DATE(2024,1,1)+(AT2-1)*7-WEEKDAY(DATE(2024,1,1),2)+7,"dd.mm") -> 23.12-29.12 | AU1: =TEXT(DATE(2025,1,1)+(AU2-1)*7-WEEKDAY(DATE(2025,1,1),2)+1,"dd.mm")&"-"&TEXT(DATE(2025,1,1)+(AU2-1)*7-WEEKDAY(DATE(2025,1,1),2)+7,"dd.mm") -> 30.12-05.01 | AV1: =TEXT(DATE(2025,1,1)+(AV2-1)*7-WEEKDAY(DATE(2025,1,1),2)+1,"dd.mm")&"-"&TEXT(DATE(2025,1,1)+(AV2-1)*7-WEEKDAY(DATE(2025,1,1),2)+7,"dd.mm") -> 06.01-12.01 | AW1: =TEXT(DATE(2025,1,1)+(AW2-1)*7-WEEKDAY(DATE(2025,1,1),2)+1,"dd.mm")&"-"&TEXT(DATE(2025,1,1)+(AW2-1)*7-WEEKDAY(DATE(2025,1,1),2)+7,"dd.mm") -> 13.01-19.01 | AX1: =TEXT(DATE(2025,1,1)+(AX2-1)*7-WEEKDAY(DATE(2025,1,1),2)+1,"dd.mm")&"-"&TEXT(DATE(2025,1,1)+(AX2-1)*7-WEEKDAY(DATE(2025,1,1),2)+7,"dd.mm") -> 20.01-26.01 | AY1: =TEXT(DATE(2025,1,1)+(AY2-1)*7-WEEKDAY(DATE(2025,1,1),2)+1,"dd.mm")&"-"&TEXT(DATE(2025,1,1)+(AY2-1)*7-WEEKDAY(DATE(2025,1,1),2)+7,"dd.mm") -> 27.01-02.02 | AZ1: =TEXT(DATE(2025,1,1)+(AZ2-1)*7-WEEKDAY(DATE(2025,1,1),2)+1,"dd.mm")&"-"&TEXT(DATE(2025,1,1)+(AZ2-1)*7-WEEKDAY(DATE(2025,1,1),2)+7,"dd.mm") -> 03.02-09.02 | BA1: =TEXT(DATE(2025,1,1)+(BA2-1)*7-WEEKDAY(DATE(2025,1,1),2)+1,"dd.mm")&"-"&TEXT(DATE(2025,1,1)+(BA2-1)*7-WEEKDAY(DATE(2025,1,1),2)+7,"dd.mm") -> 10.02-16.02 | BB1: =TEXT(DATE(2025,1,1)+(BB2-1)*7-WEEKDAY(DATE(2025,1,1),2)+1,"dd.mm")&"-"&TEXT(DATE(2025,1,1)+(BB2-1)*7-WEEKDAY(DATE(2025,1,1),2)+7,"dd.mm") -> 17.02-23.02 | ... CT1: =TEXT(DATE(2025,1,1)+(CT2-1)*7-WEEKDAY(DATE(2025,1,1),2)+1,"dd.mm")&"-"&TEXT(DATE(2025,1,1)+(CT2-1)*7-WEEKDAY(DATE(2025,1,1),2)+7,"dd.mm") -> 22.12-28.12
C2: WEEK | E2: 11 | F2: 12 | G2: 13 | H2: 14 | I2: 15 | J2: 16 | K2: 17 | L2: 18 | M2: 19 | N2: 20 | O2: 21 | P2: 22 | Q2: 23 | R2: 24 | S2: 25 | T2: 26 | U2: 27 | V2: 28 | W2: 29 | X2: 30 | Y2: 31 | Z2: 32 | AA2: 33 | AB2: 34 | AC2: 35 | AD2: 36 | AE2: 37 | AF2: 38 | AG2: 39 | AH2: 40 | AI2: 41 | AJ2: 42 | AK2: 43 | AL2: 44 | AM2: 45 | AN2: 46 | AO2: 47 | AP2: 48 | AQ2: 49 | AR2: 50 | AS2: 51 | AT2: 52 | AU2: 1 | AV2: 2 | AW2: 3 | AX2: 4 | AY2: 5 | AZ2: 6 | BA2: 7 | BB2: 8 | BC2: 9 | BD2: 10 | BE2: 11 | BF2: 12 | BG2: 13 | BH2: 14 | BI2: 15 | BJ2: 16 | BK2: 17 | BL2: 18 | BM2: 19 | BN2: 20 | BO2: 21 | BP2: 22 | BQ2: 23 | BR2: 24 | BS2: 25 | BT2: 26 | BU2: 27 | BV2: 28 | BW2: 29 | BX2: 30 | BY2: 31 | BZ2: 32 | CA2: 33 | CB2: 34 | CC2: 35 | CD2: 36 | CE2: 37 | CF2: 38 | CG2: 39 | CH2: 40 | CI2: 41 | CJ2: 42 | CK2: 43 | CL2: 44 | CM2: 45 | CN2: 46 | CO2: 47 | CP2: 48 | CQ2: 49 | CR2: 50 | CS2: 51 | CT2: 52
B3: PROJECTS & FUNCTIONALITIES CAPACITY | C3: ALF | E3: =CAPACITY!G2 -> 27.342 | F3: =OFFSET(CAPACITY!$G$2,0,7*(F$2-$E$2)) -> 27.342 | G3: =OFFSET(CAPACITY!$G$2,0,7*(G$2-$E$2)) -> 27.342 | H3: =OFFSET(CAPACITY!$G$2,0,7*(H$2-$E$2)) -> 21.462 | I3: =OFFSET(CAPACITY!$G$2,0,7*(I$2-$E$2)) -> 27.342 | J3: =OFFSET(CAPACITY!$G$2,0,7*(J$2-$E$2)) -> 27.342 | K3: =OFFSET(CAPACITY!$G$2,0,7*(K$2-$E$2)) -> 27.342 | L3: =OFFSET(CAPACITY!$G$2,0,7*(L$2-$E$2)) -> 14.028 | M3: =OFFSET(CAPACITY!$G$2,0,7*(M$2-$E$2)) -> 28.371 | ... AT3: =OFFSET(CAPACITY!$G$2,0,7*(AT$2-$E$2)) -> 12.39 | AU3: =OFFSET(CAPACITY!$G$2,0,7*(AU$2+52-$E$2)) -> 17.346 | AV3: =OFFSET(CAPACITY!$G$2,0,7*(AV$2+52-$E$2)) -> 23.247 | AW3: =OFFSET(CAPACITY!$G$2,0,7*(AW$2+52-$E$2)) -> 28.728 | AX3: =OFFSET(CAPACITY!$G$2,0,7*(AX$2+52-$E$2)) -> 28.728 | AY3: =OFFSET(CAPACITY!$G$2,0,7*(AY$2+52-$E$2)) -> 26.439 | AZ3: =OFFSET(CAPACITY!$G$2,0,7*(AZ$2+52-$E$2)) -> 28.455 | BA3: =OFFSET(CAPACITY!$G$2,0,7*(BA$2+52-$E$2)) -> 27.342 | BB3: =OFFSET(CAPACITY!$G$2,0,7*(BB$2+52-$E$2)) -> 28.581 | ... CT3: =OFFSET(CAPACITY!$G$2,0,7*(CT$2+52-$E$2)) -> 9.66
C4: WAREX | E4: =CAPACITY!G4 -> 10.388559 | F4: =OFFSET(CAPACITY!$G$4,0,7*(F$2-$E$2)) -> 10.388559 | G4: =OFFSET(CAPACITY!$G$4,0,7*(G$2-$E$2)) -> 10.388559 | H4: =OFFSET(CAPACITY!$G$4,0,7*(H$2-$E$2)) -> 8.1544599 | I4: =OFFSET(CAPACITY!$G$4,0,7*(I$2-$E$2)) -> 10.388559 | J4: =OFFSET(CAPACITY!$G$4,0,7*(J$2-$E$2)) -> 10.069402 | K4: =OFFSET(CAPACITY!$G$4,0,7*(K$2-$E$2)) -> 10.388559 | L4: =OFFSET(CAPACITY!$G$4,0,7*(L$2-$E$2)) -> 1.9149417 | M4: =OFFSET(CAPACITY!$G$4,0,7*(M$2-$E$2)) -> 9.4310877 | ... AT4: =OFFSET(CAPACITY!$G$4,0,7*(AT$2-$E$2)) -> 9.4151298 | AU4: =OFFSET(CAPACITY!$G$4,0,7*(AU$2+52-$E$2)) -> 13.181182 | AV4: =OFFSET(CAPACITY!$G$4,0,7*(AV$2+52-$E$2)) -> 17.665337 | AW4: =OFFSET(CAPACITY!$G$4,0,7*(AW$2+52-$E$2)) -> 21.830335 | AX4: =OFFSET(CAPACITY!$G$4,0,7*(AX$2+52-$E$2)) -> 21.830335 | AY4: =OFFSET(CAPACITY!$G$4,0,7*(AY$2+52-$E$2)) -> 20.09093 | AZ4: =OFFSET(CAPACITY!$G$4,0,7*(AZ$2+52-$E$2)) -> 21.622883 | BA4: =OFFSET(CAPACITY!$G$4,0,7*(BA$2+52-$E$2)) -> 20.777117 | BB4: =OFFSET(CAPACITY!$G$4,0,7*(BB$2+52-$E$2)) -> 21.71863 | ... CT4: =OFFSET(CAPACITY!$G$4,0,7*(CT$2+52-$E$2)) -> 7.3406097
C5: OPTIMUS | E5: =CAPACITY!G6 -> 21.241748 | F5: =OFFSET(CAPACITY!$G$6,0,7*(F$2-$E$2)) -> 21.241748 | G5: =OFFSET(CAPACITY!$G$6,0,7*(G$2-$E$2)) -> 21.241748 | H5: =OFFSET(CAPACITY!$G$6,0,7*(H$2-$E$2)) -> 16.67363 | I5: =OFFSET(CAPACITY!$G$6,0,7*(I$2-$E$2)) -> 21.241748 | J5: =OFFSET(CAPACITY!$G$6,0,7*(J$2-$E$2)) -> 21.241748 | K5: =OFFSET(CAPACITY!$G$6,0,7*(K$2-$E$2)) -> 21.241748 | L5: =OFFSET(CAPACITY!$G$6,0,7*(L$2-$E$2)) -> 8.995678 | M5: =OFFSET(CAPACITY!$G$6,0,7*(M$2-$E$2)) -> 18.395459 | ... AT5: =OFFSET(CAPACITY!$G$6,0,7*(AT$2-$E$2)) -> 7.9063577 | AU5: =OFFSET(CAPACITY!$G$6,0,7*(AU$2+52-$E$2)) -> 12.281209 | AV5: =OFFSET(CAPACITY!$G$6,0,7*(AV$2+52-$E$2)) -> 14.705825 | AW5: =OFFSET(CAPACITY!$G$6,0,7*(AW$2+52-$E$2)) -> 20.082148 | AX5: =OFFSET(CAPACITY!$G$6,0,7*(AX$2+52-$E$2)) -> 20.082148 | AY5: =OFFSET(CAPACITY!$G$6,0,7*(AY$2+52-$E$2)) -> 18.852271 | AZ5: =OFFSET(CAPACITY!$G$6,0,7*(AZ$2+52-$E$2)) -> 19.027967 | BA5: =OFFSET(CAPACITY!$G$6,0,7*(BA$2+52-$E$2)) -> 17.270999 | BB5: =OFFSET(CAPACITY!$G$6,0,7*(BB$2+52-$E$2)) -> 15.074789 | ... CT5: =OFFSET(CAPACITY!$G$6,0,7*(CT$2+52-$E$2)) -> 4.9195114
C6: MASH | E6: =CAPACITY!G8 -> 8.1375 | F6: =OFFSET(CAPACITY!$G$8,0,7*(F$2-$E$2)) -> 8.1375 | G6: =OFFSET(CAPACITY!$G$8,0,7*(G$2-$E$2)) -> 8.1375 | H6: =OFFSET(CAPACITY!$G$8,0,7*(H$2-$E$2)) -> 6.3875 | I6: =OFFSET(CAPACITY!$G$8,0,7*(I$2-$E$2)) -> 8.1375 | J6: =OFFSET(CAPACITY!$G$8,0,7*(J$2-$E$2)) -> 8.1375 | K6: =OFFSET(CAPACITY!$G$8,0,7*(K$2-$E$2)) -> 8.1375 | L6: =OFFSET(CAPACITY!$G$8,0,7*(L$2-$E$2)) -> 5.25 | M6: =OFFSET(CAPACITY!$G$8,0,7*(M$2-$E$2)) -> 8.1375 | ... AT6: =OFFSET(CAPACITY!$G$8,0,7*(AT$2-$E$2)) -> 2.205 | AU6: =OFFSET(CAPACITY!$G$8,0,7*(AU$2+52-$E$2)) -> 3.4825 | AV6: =OFFSET(CAPACITY!$G$8,0,7*(AV$2+52-$E$2)) -> 6.0375 | AW6: =OFFSET(CAPACITY!$G$8,0,7*(AW$2+52-$E$2)) -> 7.91 | AX6: =OFFSET(CAPACITY!$G$8,0,7*(AX$2+52-$E$2)) -> 7.21 | AY6: =OFFSET(CAPACITY!$G$8,0,7*(AY$2+52-$E$2)) -> 6.86 | AZ6: =OFFSET(CAPACITY!$G$8,0,7*(AZ$2+52-$E$2)) -> 6.7375 | BA6: =OFFSET(CAPACITY!$G$8,0,7*(BA$2+52-$E$2)) -> 6.16 | BB6: =OFFSET(CAPACITY!$G$8,0,7*(BB$2+52-$E$2)) -> 7.56 | ... CT6: =OFFSET(CAPACITY!$G$8,0,7*(CT$2+52-$E$2)) -> 3.15
C7: MAGENTO | E7: =CAPACITY!G10 -> 23.2875 | F7: =OFFSET(CAPACITY!$G$10,0,7*(F$2-$E$2)) -> 23.2875 | G7: =OFFSET(CAPACITY!$G$10,0,7*(G$2-$E$2)) -> 23.2875 | H7: =OFFSET(CAPACITY!$G$10,0,7*(H$2-$E$2)) -> 22.5375 | I7: =OFFSET(CAPACITY!$G$10,0,7*(I$2-$E$2)) -> 23.2875 | J7: =OFFSET(CAPACITY!$G$10,0,7*(J$2-$E$2)) -> 23.2875 | K7: =OFFSET(CAPACITY!$G$10,0,7*(K$2-$E$2)) -> 23.2875 | L7: =OFFSET(CAPACITY!$G$10,0,7*(L$2-$E$2)) -> 20.25 | M7: =OFFSET(CAPACITY!$G$10,0,7*(M$2-$E$2)) -> 24.1575 | ... AT7: =OFFSET(CAPACITY!$G$10,0,7*(AT$2-$E$2)) -> 12.1125 | AU7: =OFFSET(CAPACITY!$G$10,0,7*(AU$2+52-$E$2)) -> 15.6675 | AV7: =OFFSET(CAPACITY!$G$10,0,7*(AV$2+52-$E$2)) -> 19.18875 | AW7: =OFFSET(CAPACITY!$G$10,0,7*(AW$2+52-$E$2)) -> 24.1575 | AX7: =OFFSET(CAPACITY!$G$10,0,7*(AX$2+52-$E$2)) -> 24.1575 | AY7: =OFFSET(CAPACITY!$G$10,0,7*(AY$2+52-$E$2)) -> 24.1575 | AZ7: =OFFSET(CAPACITY!$G$10,0,7*(AZ$2+52-$E$2)) -> 24.1575 | BA7: =OFFSET(CAPACITY!$G$10,0,7*(BA$2+52-$E$2)) -> 24.1575 | BB7: =OFFSET(CAPACITY!$G$10,0,7*(BB$2+52-$E$2)) -> 24.1575 | ... CT7: =OFFSET(CAPACITY!$G$10,0,7*(CT$2+52-$E$2)) -> 7.5
B8: PROJECTS & FUNCTIONALITIES CAPACITY UTILISATION | C8: ALF | E8: =E3-SUMIF($C$13:$C$506,$C8,E13:E506) -> 15.342 | F8: =F3-SUMIF($C$13:$C$506,$C8,F13:F506) -> 15.342 | G8: =G3-SUMIF($C$13:$C$506,$C8,G13:G506) -> 15.342 | H8: =H3-SUMIF($C$13:$C$506,$C8,H13:H506) -> 9.462 | I8: =I3-SUMIF($C$13:$C$506,$C8,I13:I506) -> 15.342 | J8: =J3-SUMIF($C$13:$C$506,$C8,J13:J506) -> 15.342 | K8: =K3-SUMIF($C$13:$C$506,$C8,K13:K506) -> 5.342 | L8: =L3-SUMIF($C$13:$C$506,$C8,L13:L506) -> -3.972 | ... BI8: =BI3-SUMIF($C$13:$C$506,$C8,BI13:BI506) -> 30.702
C9: WAREX | E9: =E4-SUMIF($C$13:$C$506,$C9,E13:E506) -> 10.388559 | F9: =F4-SUMIF($C$13:$C$506,$C9,F13:F506) -> 10.388559 | G9: =G4-SUMIF($C$13:$C$506,$C9,G13:G506) -> 10.388559 | H9: =H4-SUMIF($C$13:$C$506,$C9,H13:H506) -> 0.15445992 | I9: =I4-SUMIF($C$13:$C$506,$C9,I13:I506) -> 2.3885585 | J9: =J4-SUMIF($C$13:$C$506,$C9,J13:J506) -> 2.0694016 | K9: =K4-SUMIF($C$13:$C$506,$C9,K13:K506) -> -3.6114415 | L9: =L4-SUMIF($C$13:$C$506,$C9,L13:L506) -> -4.0850583 | ... BI9: =BI4-SUMIF($C$13:$C$506,$C9,BI13:BI506) -> 23.330373
C10: OPTIMUS | E10: =E5-SUMIF($C$13:$C$506,$C10,E13:E506) -> 21.241748 | F10: =F5-SUMIF($C$13:$C$506,$C10,F13:F506) -> 21.241748 | G10: =G5-SUMIF($C$13:$C$506,$C10,G13:G506) -> 21.241748 | H10: =H5-SUMIF($C$13:$C$506,$C10,H13:H506) -> 16.67363 | I10: =I5-SUMIF($C$13:$C$506,$C10,I13:I506) -> 21.241748 | J10: =J5-SUMIF($C$13:$C$506,$C10,J13:J506) -> 21.241748 | K10: =K5-SUMIF($C$13:$C$506,$C10,K13:K506) -> 21.241748 | L10: =L5-SUMIF($C$13:$C$506,$C10,L13:L506) -> 8.995678 | ... BI10: =BI5-SUMIF($C$13:$C$506,$C10,BI13:BI506) -> 17.868368
C11: MASH | E11: =E6-SUMIF($C$13:$C$506,$C11,E13:E506) -> 7.6375 | F11: =F6-SUMIF($C$13:$C$506,$C11,F13:F506) -> 7.6375 | G11: =G6-SUMIF($C$13:$C$506,$C11,G13:G506) -> 7.6375 | H11: =H6-SUMIF($C$13:$C$506,$C11,H13:H506) -> 4.8875 | I11: =I6-SUMIF($C$13:$C$506,$C11,I13:I506) -> 5.6375 | J11: =J6-SUMIF($C$13:$C$506,$C11,J13:J506) -> 3.6375 | K11: =K6-SUMIF($C$13:$C$506,$C11,K13:K506) -> 0.6375 | L11: =L6-SUMIF($C$13:$C$506,$C11,L13:L506) -> -2.25 | ... BI11: =BI6-SUMIF($C$13:$C$506,$C11,BI13:BI506) -> 8.1375
C12: MAGENTO | E12: =E7-SUMIF($C$13:$C$506,$C12,E13:E506) -> 23.2875 | F12: =F7-SUMIF($C$13:$C$506,$C12,F13:F506) -> 23.2875 | G12: =G7-SUMIF($C$13:$C$506,$C12,G13:G506) -> 23.2875 | H12: =H7-SUMIF($C$13:$C$506,$C12,H13:H506) -> 22.5375 | I12: =I7-SUMIF($C$13:$C$506,$C12,I13:I506) -> 23.2875 | J12: =J7-SUMIF($C$13:$C$506,$C12,J13:J506) -> 11.2875 | K12: =K7-SUMIF($C$13:$C$506,$C12,K13:K506) -> 0.2875 | L12: =L7-SUMIF($C$13:$C$506,$C12,L13:L506) -> 2.25 | ... BI12: =BI7-SUMIF($C$13:$C$506,$C12,BI13:BI506) -> 24.4125
B13: DŁUG FUNKCJONALNY ALF | C13: ALF | D13: =SUM(E13:CT13) -> 504 | E13: 12 | F13: 12 | G13: 12 | H13: 12 | I13: 12 | J13: 12 | K13: 12 | L13: 12 | M13: 12 | N13: 12 | O13: 12 | P13: 12 | Q13: 12 | R13: 12 | S13: 12 | T13: 12 | U13: 12 | V13: 12 | W13: 12 | X13: 12 | Y13: 12 | Z13: 12 | AA13: 12 | AB13: 12 | AC13: 12 | AD13: 12 | AE13: 12 | AF13: 12 | AG13: 12 | AH13: 12 | AI13: 12 | AJ13: 12 | AK13: 12 | AL13: 12 | AM13: 12 | AN13: 12 | AO13: 12 | AP13: 12 | AQ13: 12 | AR13: 12 | AS13: 12 | AT13: 12
C14: WAREX | D14: =SUM(E14:CT14) -> 0
C15: OPTIMUS | D15: =SUM(E15:CT15) -> 0
C16: MASH | D16: =SUM(E16:CT16) -> 21 | E16: 0.5 | F16: 0.5 | G16: 0.5 | H16: 0.5 | I16: 0.5 | J16: 0.5 | K16: 0.5 | L16: 0.5 | M16: 0.5 | N16: 0.5 | O16: 0.5 | P16: 0.5 | Q16: 0.5 | R16: 0.5 | S16: 0.5 | T16: 0.5 | U16: 0.5 | V16: 0.5 | W16: 0.5 | X16: 0.5 | Y16: 0.5 | Z16: 0.5 | AA16: 0.5 | AB16: 0.5 | AC16: 0.5 | AD16: 0.5 | AE16: 0.5 | AF16: 0.5 | AG16: 0.5 | AH16: 0.5 | AI16: 0.5 | AJ16: 0.5 | AK16: 0.5 | AL16: 0.5 | AM16: 0.5 | AN16: 0.5 | AO16: 0.5 | AP16: 0.5 | AQ16: 0.5 | AR16: 0.5 | AS16: 0.5 | AT16: 0.5
C17: MAGENTO | D17: =SUM(E17:CT17) -> 0
A18: 0 | B18: Project - Portal B2B 1(1.5) | C18: ALF | D18: =SUM(E18:CT18) -> 2 | K18: 2
C19: WAREX | D19: =SUM(E19:CT19) -> 0
C20: OPTIMUS | D20: =SUM(E20:CT20) -> 0
C21: MASH | D21: =SUM(E21:CT21) -> 2 | J21: 1 | M21: 1
C22: MAGENTO | D22: =SUM(E22:CT22) -> 27 | J22: 6 | K22: 3 | L22: 3 | M22: 3 | N22: 2 | R22: 5 | S22: 5
A23: 0 | B23: Project - Multibrand for iMad | C23: ALF | D23: =SUM(E23:CT23) -> 2 | K23: 2
C24: WAREX | D24: =SUM(E24:CT24) -> 0
C25: OPTIMUS | D25: =SUM(E25:CT25) -> 0
C26: MASH | D26: =SUM(E26:CT26) -> 1 | K26: 1
C27: MAGENTO | D27: =SUM(E27:CT27) -> 35 | K27: 5 | L27: 5 | M27: 5 | Q27: 5 | R27: 5 | S27: 5 | T27: 5
A28: 0 | B28: Project - Malezja Faza 1A | C28: ALF | D28: =SUM(E28:CT28) -> 8.5 | K28: 1 | L28: 1 | M28: 0.5 | O28: 1 | P28: 3 | Q28: 2
C29: WAREX | D29: =SUM(E29:CT29) -> 1 | M29: 0.5 | N29: 0.5
C30: OPTIMUS | D30: =SUM(E30:CT30) -> 8 | P30: 0.5 | Q30: 0.5 | R30: 5 | S30: 2
C31: MASH | D31: =SUM(E31:CT31) -> 20 | H31: 1 | I31: 2 | J31: 3 | K31: 3 | L31: 2 | M31: 3 | N31: 1 | P31: 0.5 | Q31: 1 | R31: 0.5 | S31: 1 | T31: 2
C32: MAGENTO | D32: =SUM(E32:CT32) -> 92 | J32: 6 | K32: 15 | L32: 10 | M32: 5 | N32: 15 | O32: 15 | P32: 10 | Q32: 5 | R32: 4 | S32: 4 | T32: 3
A33: 0 | B33: MM Open Days: Faza1 - 22/05 | C33: ALF | D33: =SUM(E33:CT33) -> 25 | K33: 5 | L33: 5 | M33: 5 | N33: 5 | O33: 5
C34: WAREX | D34: =SUM(E34:CT34) -> 2 | N34: 2
C35: OPTIMUS | D35: =SUM(E35:CT35) -> 0
C36: MASH | D36: =SUM(E36:CT36) -> 15 | K36: 3 | L36: 5 | M36: 3 | N36: 2 | O36: 2
C37: MAGENTO | D37: =SUM(E37:CT37) -> 10 | N37: 5 | O37: 5
A38: 0 | B38: MM Open Days: Faza2 - 03/06 | C38: ALF | D38: =SUM(E38:CT38) -> 0
C39: WAREX | D39: =SUM(E39:CT39) -> 0
C40: OPTIMUS | D40: =SUM(E40:CT40) -> 0
...

Sheet WORKLOAD_PEOPLE
A1: NAME | B1: SURNAME | C1: FULL NAME | D1: SKILLSET | E1: TEAM | F1: PROJECT | G1: TOTAL PROJECT MD | H1: 45362 | I1: 45363 | J1: 45364 | K1: 45365 | L1: 45366 | M1: 45367 | N1: 45368 | O1: 45369 | P1: 45370 | Q1: 45371 | R1: 45372 | S1: 45373 | T1: 45374 | U1: 45375 | V1: 45376 | W1: 45377 | X1: 45378 | Y1: 45379 | Z1: 45380 | AA1: 45381 | AB1: 45382 | AC1: 45383 | AD1: 45384 | AE1: 45385 | AF1: 45386 | AG1: 45387 | AH1: 45388 | AI1: 45389 | AJ1: 45390 | AK1: 45391 | AL1: 45392 | AM1: 45393 | AN1: 45394 | AO1: 45395 | AP1: 45396 | AQ1: 45397 | AR1: 45398 | AS1: 45399 | AT1: 45400 | AU1: 45401 | AV1: 45402 | AW1: 45403 | AX1: 45404 | AY1: 45405 | AZ1: 45406 | BA1: 45407 | BB1: 45408 | BC1: 45409 | BD1: 45410 | BE1: 45411 | BF1: 45412 | BG1: 45413 | BH1: 45414 | BI1: 45415 | BJ1: 45416 | BK1: 45417 | BL1: 45418 | BM1: 45419 | BN1: 45420 | BO1: 45421 | BP1: 45422 | BQ1: 45423 | BR1: 45424 | BS1: 45425 | BT1: 45426 | BU1: 45427 | BV1: 45428 | BW1: 45429 | BX1: 45430 | BY1: 45431 | BZ1: 45432 | CA1: 45433 | CB1: 45434 | CC1: 45435 | CD1: 45436 | CE1: 45437 | CF1: 45438 | CG1: 45439 | CH1: 45440 | CI1: 45441 | CJ1: 45442 | CK1: 45443 | CL1: 45444 | CM1: 45445 | CN1: 45446 | CO1: 45447 | CP1: 45448 | CQ1: 45449 | CR1: 45450 | CS1: 45451 | CT1: 45452 | CU1: 45453 | CV1: 45454 | CW1: 45455 | CX1: 45456 | CY1: 45457 | CZ1: 45458 | DA1: 45459 | DB1: 45460 | DC1: 45461 | DD1: 45462 | DE1: 45463 | DF1: 45464 | DG1: 45465 | DH1: 45466 | DI1: 45467 | DJ1: 45468 | DK1: 45469 | DL1: 45470 | DM1: 45471 | DN1: 45472 | DO1: 45473 | DP1: 45474 | DQ1: 45475 | DR1: 45476 | DS1: 45477 | DT1: 45478 | DU1: 45479 | DV1: 45480 | DW1: 45481 | DX1: 45482 | DY1: 45483 | DZ1: 45484 | EA1: 45485 | EB1: 45486 | EC1: 45487 | ED1: 45488 | EE1: 45489 | EF1: 45490 | EG1: 45491 | EH1: 45492 | EI1: 45493 | EJ1: 45494 | EK1: 45495 | EL1: 45496 | EM1: 45497 | EN1: 45498 | EO1: 45499 | EP1: 45500 | EQ1: 45501 | ER1: 45502 | ES1: 45503 | ET1: 45504 | EU1: 45505 | EV1: 45506 | EW1: 45507 | EX1: 45508 | EY1: 45509 | EZ1: 45510 | FA1: 45511 | FB1: 45512 | FC1: 45513 | FD1: 45514 | FE1: 45515 | FF1: 45516 | FG1: 45517 | FH1: 45518 | FI1: 45519 | FJ1: 45520 | FK1: 45521 | FL1: 45522 | FM1: 45523 | FN1: 45524 | FO1: 45525 | FP1: 45526 | FQ1: 45527 | FR1: 45528 | FS1: 45529 | FT1: 45530 | FU1: 45531 | FV1: 45532 | FW1: 45533 | FX1: 45534 | FY1: 45535 | FZ1: 45536 | GA1: 45537 | GB1: 45538 | GC1: 45539 | GD1: 45540 | GE1: 45541 | GF1: 45542 | GG1: 45543 | GH1: 45544 | GI1: 45545 | GJ1: 45546 | GK1: 45547 | GL1: 45548 | GM1: 45549 | GN1: 45550 | GO1: 45551 | GP1: 45552 | GQ1: 45553 | GR1: 45554 | GS1: 45555 | GT1: 45556 | GU1: 45557 | GV1: 45558 | GW1: 45559 | GX1: 45560 | GY1: 45561 | GZ1: 45562 | HA1: 45563 | HB1: 45564 | HC1: 45565 | HD1: 45566 | HE1: 45567 | HF1: 45568 | HG1: 45569 | HH1: 45570 | HI1: 45571 | HJ1: 45572 | HK1: 45573 | HL1: 45574 | HM1: 45575 | HN1: 45576 | HO1: 45577 | HP1: 45578 | HQ1: 45579 | HR1: 45580 | HS1: 45581 | HT1: 45582 | HU1: 45583 | HV1: 45584 | HW1: 45585 | HX1: 45586 | HY1: 45587 | HZ1: 45588 | IA1: 45589 | IB1: 45590 | IC1: 45591 | ID1: 45592 | IE1: 45593 | IF1: 45594 | IG1: 45595 | IH1: 45596 | II1: 45597 | IJ1: 45598 | IK1: 45599 | IL1: 45600 | IM1: 45601 | IN1: 45602 | IO1: 45603 | IP1: 45604 | IQ1: 45605 | IR1: 45606 | IS1: 45607 | IT1: 45608 | IU1: 45609 | IV1: 45610 | IW1: 45611 | IX1: 45612 | IY1: 45613 | IZ1: 45614 | JA1: 45615 | JB1: 45616 | JC1: 45617 | JD1: 45618 | JE1: 45619 | JF1: 45620 | JG1: 45621 | JH1: 45622 | JI1: 45623 | JJ1: 45624 | JK1: 45625 | JL1: 45626 | JM1: 45627 | JN1: 45628 | JO1: 45629 | JP1: 45630 | JQ1: 45631 | JR1: 45632 | JS1: 45633 | JT1: 45634 | JU1: 45635 | JV1: 45636 | JW1: 45637 | JX1: 45638 | JY1: 45639 | JZ1: 45640 | KA1: 45641 | KB1: 45642 | KC1: 45643 | KD1: 45644 | KE1: 45645 | KF1: 45646 | KG1: 45647 | KH1: 45648 | KI1: 45649 | KJ1: 45650 | KK1: 45651 | KL1: 45652 | KM1: 45653 | KN1: 45654 | KO1: 45655 | KP1: 45656 | KQ1: 45657 | KR1: 45658 | KS1: 45659 | KT1: 45660 | KU1: 45661 | KV1: 45662 | KW1: 45663 | KX1: 45664 | KY1: 45665 | KZ1: 45666 | LA1: 45667 | LB1: 45668
A2: Andrzej | B2: Dyśko | C2: =A2&" "&B2 -> Andrzej Dyśko | D2: =VLOOKUP(C2,CAPACITY!$C$12:$E$69,2,0) -> #N/A | E2: =VLOOKUP(C2,CAPACITY!$C$12:$E$69,3,0) -> #N/A | F2: SUMA | G2: =SUM(H2:L2) -> 0.65 | H2: =SUM(H3:H5) -> 0.35 | I2: =SUM(I3:I5) -> 0.1 | J2: =SUM(J3:J5) -> 0.1 | K2: =SUM(K3:K5) -> 0.1 | L2: =SUM(L3:L5) -> 0 | M2: =SUM(M3:M5) -> 0 | N2: =SUM(N3:N5) -> 0 | O2: =SUM(O3:O5) -> 0 | ... LB2: =SUM(LB3:LB5) -> 0
A3: Andrzej | B3: Dyśko | C3: =A3&" "&B3 -> Andrzej Dyśko | D3: =VLOOKUP(C3,CAPACITY!$C$12:$E$69,2,0) -> #N/A | E3: =VLOOKUP(C3,CAPACITY!$C$12:$E$69,3,0) -> #N/A | F3: Malezja | G3: =SUM(H3:L3) -> 0.35 | H3: 0.05 | I3: 0.1 | J3: 0.1 | K3: 0.1 | L3: 0 | M3: 0 | N3: 0 | O3: 0 | P3: 0 | Q3: 0 | R3: 0 | S3: 0 | T3: 0 | U3: 0 | V3: 0 | W3: 0 | X3: 0 | Y3: 0 | Z3: 0 | AA3: 0 | AB3: 0 | AC3: 0 | AD3: 0 | AE3: 0 | AF3: 0 | AG3: 0 | AH3: 0 | AI3: 0 | AJ3: 0 | AK3: 0 | AL3: 0 | AM3: 0 | AN3: 0 | AO3: 0 | AP3: 0 | AQ3: 0 | AR3: 0 | AS3: 0 | AT3: 0 | AU3: 0 | AV3: 0 | AW3: 0 | AX3: 0 | AY3: 0 | AZ3: 0 | BA3: 0 | BB3: 0 | BC3: 0 | BD3: 0 | BE3: 0 | BF3: 0 | BG3: 0 | BH3: 0 | BI3: 0 | BJ3: 0 | BK3: 0 | BL3: 0 | BM3: 0 | BN3: 0 | BO3: 0 | BP3: 0 | BQ3: 0 | BR3: 0 | BS3: 0 | BT3: 0 | BU3: 0 | BV3: 0 | BW3: 0 | BX3: =SUM(BX4:BX6) -> 0 | BY3: =SUM(BY4:BY6) -> 0 | BZ3: 0 | CA3: 0 | CB3: 0 | CC3: 0 | CD3: 0 | CE3: 0 | CF3: 0 | CG3: 0 | CH3: 0 | CI3: 0 | CJ3: 0 | CK3: 0 | CL3: 0 | CM3: 0 | CN3: 0 | CO3: 0 | CP3: 0 | CQ3: 0 | CR3: 0 | CS3: 0 | CT3: 0 | CU3: 0 | CV3: 0 | CW3: 0 | CX3: 0 | CY3: 0 | CZ3: 0 | DA3: 0 | DB3: 0 | DC3: 0 | DD3: 0 | DE3: 0 | DF3: 0 | DG3: 0 | DH3: 0 | DI3: 0 | DJ3: 0 | DK3: 0 | DL3: 0 | DM3: 0 | DN3: 0 | DO3: 0 | DP3: 0 | DQ3: 0 | DR3: 0 | DS3: 0 | DT3: 0 | DU3: 0 | DV3: 0 | DW3: 0 | DX3: 0 | DY3: 0 | DZ3: 0 | EA3: 0 | EB3: 0 | EC3: 0 | ED3: 0 | EE3: 0 | EF3: 0 | EG3: 0 | EH3: 0 | EI3: 0 | EJ3: 0 | EK3: 0 | EL3: 0 | EM3: 0 | EN3: 0 | EO3: 0 | EP3: 0 | EQ3: 0 | ER3: 0 | ES3: 0 | ET3: 0 | EU3: 0 | EV3: 0 | EW3: 0 | EX3: 0 | EY3: 0 | EZ3: 0 | FA3: 0 | FB3: 0 | FC3: 0 | FD3: 0 | FE3: 0 | FF3: 0 | FG3: 0 | FH3: 0 | FI3: 0 | FJ3: 0 | FK3: 0 | FL3: 0 | FM3: 0 | FN3: 0 | FO3: 0 | FP3: 0 | FQ3: 0 | FR3: 0 | FS3: 0 | FT3: 0 | FU3: 0 | FV3: 0 | FW3: 0 | FX3: 0 | FY3: 0 | FZ3: 0 | GA3: 0 | GB3: 0 | GC3: 0 | GD3: 0 | GE3: 0 | GF3: 0 | GG3: 0 | GH3: 0 | GI3: 0 | GJ3: 0 | GK3: 0 | GL3: 0 | GM3: 0 | GN3: 0 | GO3: 0 | GP3: 0 | GQ3: 0 | GR3: 0 | GS3: 0 | GT3: 0 | GU3: 0 | GV3: 0 | GW3: 0 | GX3: 0 | GY3: 0 | GZ3: 0 | HA3: 0 | HB3: 0 | HC3: 0 | HD3: 0 | HE3: 0 | HF3: 0 | HG3: 0 | HH3: 0 | HI3: 0 | HJ3: 0 | HK3: 0 | HL3: 0 | HM3: 0 | HN3: 0 | HO3: 0 | HP3: 0 | HQ3: 0 | HR3: 0 | HS3: 0 | HT3: 0 | HU3: 0 | HV3: 0 | HW3: 0 | HX3: 0 | HY3: 0 | HZ3: 0 | IA3: 0 | IB3: 0 | IC3: 0 | ID3: 0 | IE3: 0 | IF3: 0 | IG3: 0 | IH3: 0 | II3: 0 | IJ3: 0 | IK3: 0 | IL3: 0 | IM3: 0 | IN3: 0 | IO3: 0 | IP3: 0 | IQ3: 0 | IR3: 0 | IS3: 0 | IT3: 0 | IU3: 0 | IV3: 0 | IW3: 0 | IX3: 0 | IY3: 0 | IZ3: 0 | JA3: 0 | JB3: 0 | JC3: 0 | JD3: 0 | JE3: 0 | JF3: 0 | JG3: 0 | JH3: 0 | JI3: 0 | JJ3: 0 | JK3: 0 | JL3: 0 | JM3: 0 | JN3: 0 | JO3: 0 | JP3: 0 | JQ3: 0 | JR3: 0 | JS3: 0 | JT3: 0 | JU3: 0 | JV3: 0 | JW3: 0 | JX3: 0 | JY3: 0 | JZ3: 0 | KA3: 0 | KB3: 0 | KC3: 0 | KD3: 0 | KE3: 0 | KF3: 0 | KG3: 0 | KH3: 0 | KI3: 0 | KJ3: 0 | KK3: 0 | KL3: 0 | KM3: 0 | KN3: 0 | KO3: 0 | KP3: 0 | KQ3: 0 | KR3: 0 | KS3: 0 | KT3: 0 | KU3: 0 | KV3: 0 | KW3: 0 | KX3: 0 | KY3: 0 | KZ3: 0 | LA3: 0 | LB3: 0
A4: Andrzej | B4: Dyśko | C4: =A4&" "&B4 -> Andrzej Dyśko | D4: =VLOOKUP(C4,CAPACITY!$C$12:$E$69,2,0) -> #N/A | E4: =VLOOKUP(C4,CAPACITY!$C$12:$E$69,3,0) -> #N/A | F4: KYC | G4: =SUM(H4:L4) -> 0.1 | H4: 0.1 | I4: 0 | J4: 0 | K4: 0 | L4: 0 | M4: 0 | N4: 0 | O4: 0 | P4: 0 | Q4: 0 | R4: 0 | S4: 0 | T4: 0 | U4: 0 | V4: 0 | W4: 0 | X4: 0 | Y4: 0 | Z4: 0 | AA4: 0 | AB4: 0 | AC4: 0 | AD4: 0 | AE4: 0 | AF4: 0 | AG4: 0 | AH4: 0 | AI4: 0 | AJ4: 0 | AK4: 0 | AL4: 0 | AM4: 0 | AN4: 0 | AO4: 0 | AP4: 0 | AQ4: 0 | AR4: 0 | AS4: 0 | AT4: 0 | AU4: 0 | AV4: 0 | AW4: 0 | AX4: 0 | AY4: 0 | AZ4: 0 | BA4: 0 | BB4: 0 | BC4: 0 | BD4: 0 | BE4: 0 | BF4: 0 | BG4: 0 | BH4: 0 | BI4: 0 | BJ4: 0 | BK4: 0 | BL4: 0 | BM4: 0 | BN4: 0 | BO4: 0 | BP4: 0 | BQ4: 0 | BR4: 0 | BS4: 0 | BT4: 0 | BU4: 0 | BV4: 0 | BW4: 0 | BX4: =SUM(BX5:BX7) -> 0 | BY4: =SUM(BY5:BY7) -> 0 | BZ4: 0 | CA4: 0 | CB4: 0 | CC4: 0 | CD4: 0 | CE4: 0 | CF4: 0 | CG4: 0 | CH4: 0 | CI4: 0 | CJ4: 0 | CK4: 0 | CL4: 0 | CM4: 0 | CN4: 0 | CO4: 0 | CP4: 0 | CQ4: 0 | CR4: 0 | CS4: 0 | CT4: 0 | CU4: 0 | CV4: 0 | CW4: 0 | CX4: 0 | CY4: 0 | CZ4: 0 | DA4: 0 | DB4: 0 | DC4: 0 | DD4: 0 | DE4: 0 | DF4: 0 | DG4: 0 | DH4: 0 | DI4: 0 | DJ4: 0 | DK4: 0 | DL4: 0 | DM4: 0 | DN4: 0 | DO4: 0 | DP4: 0 | DQ4: 0 | DR4: 0 | DS4: 0 | DT4: 0 | DU4: 0 | DV4: 0 | DW4: 0 | DX4: 0 | DY4: 0 | DZ4: 0 | EA4: 0 | EB4: 0 | EC4: 0 | ED4: 0 | EE4: 0 | EF4: 0 | EG4: 0 | EH4: 0 | EI4: 0 | EJ4: 0 | EK4: 0 | EL4: 0 | EM4: 0 | EN4: 0 | EO4: 0 | EP4: 0 | EQ4: 0 | ER4: 0 | ES4: 0 | ET4: 0 | EU4: 0 | EV4: 0 | EW4: 0 | EX4: 0 | EY4: 0 | EZ4: 0 | FA4: 0 | FB4: 0 | FC4: 0 | FD4: 0 | FE4: 0 | FF4: 0 | FG4: 0 | FH4: 0 | FI4: 0 | FJ4: 0 | FK4: 0 | FL4: 0 | FM4: 0 | FN4: 0 | FO4: 0 | FP4: 0 | FQ4: 0 | FR4: 0 | FS4: 0 | FT4: 0 | FU4: 0 | FV4: 0 | FW4: 0 | FX4: 0 | FY4: 0 | FZ4: 0 | GA4: 0 | GB4: 0 | GC4: 0 | GD4: 0 | GE4: 0 | GF4: 0 | GG4: 0 | GH4: 0 | GI4: 0 | GJ4: 0 | GK4: 0 | GL4: 0 | GM4: 0 | GN4: 0 | GO4: 0 | GP4: 0 | GQ4: 0 | GR4: 0 | GS4: 0 | GT4: 0 | GU4: 0 | GV4: 0 | GW4: 0 | GX4: 0 | GY4: 0 | GZ4: 0 | HA4: 0 | HB4: 0 | HC4: 0 | HD4: 0 | HE4: 0 | HF4: 0 | HG4: 0 | HH4: 0 | HI4: 0 | HJ4: 0 | HK4: 0 | HL4: 0 | HM4: 0 | HN4: 0 | HO4: 0 | HP4: 0 | HQ4: 0 | HR4: 0 | HS4: 0 | HT4: 0 | HU4: 0 | HV4: 0 | HW4: 0 | HX4: 0 | HY4: 0 | HZ4: 0 | IA4: 0 | IB4: 0 | IC4: 0 | ID4: 0 | IE4: 0 | IF4: 0 | IG4: 0 | IH4: 0 | II4: 0 | IJ4: 0 | IK4: 0 | IL4: 0 | IM4: 0 | IN4: 0 | IO4: 0 | IP4: 0 | IQ4: 0 | IR4: 0 | IS4: 0 | IT4: 0 | IU4: 0 | IV4: 0 | IW4: 0 | IX4: 0 | IY4: 0 | IZ4: 0 | JA4: 0 | JB4: 0 | JC4: 0 | JD4: 0 | JE4: 0 | JF4: 0 | JG4: 0 | JH4: 0 | JI4: 0 | JJ4: 0 | JK4: 0 | JL4: 0 | JM4: 0 | JN4: 0 | JO4: 0 | JP4: 0 | JQ4: 0 | JR4: 0 | JS4: 0 | JT4: 0 | JU4: 0 | JV4: 0 | JW4: 0 | JX4: 0 | JY4: 0 | JZ4: 0 | KA4: 0 | KB4: 0 | KC4: 0 | KD4: 0 | KE4: 0 | KF4: 0 | KG4: 0 | KH4: 0 | KI4: 0 | KJ4: 0 | KK4: 0 | KL4: 0 | KM4: 0 | KN4: 0 | KO4: 0 | KP4: 0 | KQ4: 0 | KR4: 0 | KS4: 0 | KT4: 0 | KU4: 0 | KV4: 0 | KW4: 0 | KX4: 0 | KY4: 0 | KZ4: 0 | LA4: 0 | LB4: 0
A5: Andrzej | B5: Dyśko | C5: =A5&" "&B5 -> Andrzej Dyśko | D5: =VLOOKUP(C5,CAPACITY!$C$12:$E$69,2,0) -> #N/A | E5: =VLOOKUP(C5,CAPACITY!$C$12:$E$69,3,0) -> #N/A | F5: C | G5: =SUM(H5:L5) -> 0.2 | H5: 0.2 | I5: 0 | J5: 0 | K5: 0 | L5: 0 | M5: 0 | N5: 0 | O5: 0 | P5: 0 | Q5: 0 | R5: 0 | S5: 0 | T5: 0 | U5: 0 | V5: 0 | W5: 0 | X5: 0 | Y5: 0 | Z5: 0 | AA5: 0 | AB5: 0 | AC5: 0 | AD5: 0 | AE5: 0 | AF5: 0 | AG5: 0 | AH5: 0 | AI5: 0 | AJ5: 0 | AK5: 0 | AL5: 0 | AM5: 0 | AN5: 0 | AO5: 0 | AP5: 0 | AQ5: 0 | AR5: 0 | AS5: 0 | AT5: 0 | AU5: 0 | AV5: 0 | AW5: 0 | AX5: 0 | AY5: 0 | AZ5: 0 | BA5: 0 | BB5: 0 | BC5: 0 | BD5: 0 | BE5: 0 | BF5: 0 | BG5: 0 | BH5: 0 | BI5: 0 | BJ5: 0 | BK5: 0 | BL5: 0 | BM5: 0 | BN5: 0 | BO5: 0 | BP5: 0 | BQ5: 0 | BR5: 0 | BS5: 0 | BT5: 0 | BU5: 0 | BV5: 0 | BW5: 0 | BX5: =SUM(BX6:BX8) -> 0 | BY5: =SUM(BY6:BY8) -> 0 | BZ5: 0 | CA5: 0 | CB5: 0 | CC5: 0 | CD5: 0 | CE5: 0 | CF5: 0 | CG5: 0 | CH5: 0 | CI5: 0 | CJ5: 0 | CK5: 0 | CL5: 0 | CM5: 0 | CN5: 0 | CO5: 0 | CP5: 0 | CQ5: 0 | CR5: 0 | CS5: 0 | CT5: 0 | CU5: 0 | CV5: 0 | CW5: 0 | CX5: 0 | CY5: 0 | CZ5: 0 | DA5: 0 | DB5: 0 | DC5: 0 | DD5: 0 | DE5: 0 | DF5: 0 | DG5: 0 | DH5: 0 | DI5: 0 | DJ5: 0 | DK5: 0 | DL5: 0 | DM5: 0 | DN5: 0 | DO5: 0 | DP5: 0 | DQ5: 0 | DR5: 0 | DS5: 0 | DT5: 0 | DU5: 0 | DV5: 0 | DW5: 0 | DX5: 0 | DY5: 0 | DZ5: 0 | EA5: 0 | EB5: 0 | EC5: 0 | ED5: 0 | EE5: 0 | EF5: 0 | EG5: 0 | EH5: 0 | EI5: 0 | EJ5: 0 | EK5: 0 | EL5: 0 | EM5: 0 | EN5: 0 | EO5: 0 | EP5: 0 | EQ5: 0 | ER5: 0 | ES5: 0 | ET5: 0 | EU5: 0 | EV5: 0 | EW5: 0 | EX5: 0 | EY5: 0 | EZ5: 0 | FA5: 0 | FB5: 0 | FC5: 0 | FD5: 0 | FE5: 0 | FF5: 0 | FG5: 0 | FH5: 0 | FI5: 0 | FJ5: 0 | FK5: 0 | FL5: 0 | FM5: 0 | FN5: 0 | FO5: 0 | FP5: 0 | FQ5: 0 | FR5: 0 | FS5: 0 | FT5: 0 | FU5: 0 | FV5: 0 | FW5: 0 | FX5: 0 | FY5: 0 | FZ5: 0 | GA5: 0 | GB5: 0 | GC5: 0 | GD5: 0 | GE5: 0 | GF5: 0 | GG5: 0 | GH5: 0 | GI5: 0 | GJ5: 0 | GK5: 0 | GL5: 0 | GM5: 0 | GN5: 0 | GO5: 0 | GP5: 0 | GQ5: 0 | GR5: 0 | GS5: 0 | GT5: 0 | GU5: 0 | GV5: 0 | GW5: 0 | GX5: 0 | GY5: 0 | GZ5: 0 | HA5: 0 | HB5: 0 | HC5: 0 | HD5: 0 | HE5: 0 | HF5: 0 | HG5: 0 | HH5: 0 | HI5: 0 | HJ5: 0 | HK5: 0 | HL5: 0 | HM5: 0 | HN5: 0 | HO5: 0 | HP5: 0 | HQ5: 0 | HR5: 0 | HS5: 0 | HT5: 0 | HU5: 0 | HV5: 0 | HW5: 0 | HX5: 0 | HY5: 0 | HZ5: 0 | IA5: 0 | IB5: 0 | IC5: 0 | ID5: 0 | IE5: 0 | IF5: 0 | IG5: 0 | IH5: 0 | II5: 0 | IJ5: 0 | IK5: 0 | IL5: 0 | IM5: 0 | IN5: 0 | IO5: 0 | IP5: 0 | IQ5: 0 | IR5: 0 | IS5: 0 | IT5: 0 | IU5: 0 | IV5: 0 | IW5: 0 | IX5: 0 | IY5: 0 | IZ5: 0 | JA5: 0 | JB5: 0 | JC5: 0 | JD5: 0 | JE5: 0 | JF5: 0 | JG5: 0 | JH5: 0 | JI5: 0 | JJ5: 0 | JK5: 0 | JL5: 0 | JM5: 0 | JN5: 0 | JO5: 0 | JP5: 0 | JQ5: 0 | JR5: 0 | JS5: 0 | JT5: 0 | JU5: 0 | JV5: 0 | JW5: 0 | JX5: 0 | JY5: 0 | JZ5: 0 | KA5: 0 | KB5: 0 | KC5: 0 | KD5: 0 | KE5: 0 | KF5: 0 | KG5: 0 | KH5: 0 | KI5: 0 | KJ5: 0 | KK5: 0 | KL5: 0 | KM5: 0 | KN5: 0 | KO5: 0 | KP5: 0 | KQ5: 0 | KR5: 0 | KS5: 0 | KT5: 0 | KU5: 0 | KV5: 0 | KW5: 0 | KX5: 0 | KY5: 0 | KZ5: 0 | LA5: 0 | LB5: 0
A6: Mikołaj | B6: Banaszkiewicz | C6: =A6&" "&B6 -> Mikołaj Banaszkiewicz | D6: =VLOOKUP(C6,CAPACITY!$C$12:$E$69,2,0) -> BE Developer | E6: =VLOOKUP(C6,CAPACITY!$C$12:$E$69,3,0) -> ALF | BI6: =SUM(BI7:BI9) -> 0 | BJ6: =SUM(BJ7:BJ9) -> 0 | BK6: =SUM(BK7:BK9) -> 0 | BL6: =SUM(BL7:BL9) -> 0 | BM6: =SUM(BM7:BM9) -> 0 | BN6: =SUM(BN7:BN9) -> 0 | BO6: =SUM(BO7:BO9) -> 0 | BP6: =SUM(BP7:BP9) -> 0 | ... CF6: =SUM(CF7:CF9) -> 0
A7: Mikołaj | B7: Banaszkiewicz | C7: =A7&" "&B7 -> Mikołaj Banaszkiewicz | D7: =VLOOKUP(C7,CAPACITY!$C$12:$E$69,2,0) -> BE Developer | E7: =VLOOKUP(C7,CAPACITY!$C$12:$E$69,3,0) -> ALF | BI7: 0 | BJ7: 0 | BK7: 0 | BL7: 0 | BM7: 0 | BN7: 0 | BO7: 0 | BP7: 0 | BQ7: 0 | BR7: 0 | BS7: 0 | BT7: 0 | BU7: 0 | BV7: 0 | BW7: 0 | BX7: =SUM(BX8:BX10) -> 0 | BY7: =SUM(BY8:BY10) -> 0 | BZ7: 0 | CA7: 0 | CB7: 0 | CC7: 0 | CD7: 0 | CE7: 0 | CF7: 0
A8: Mikołaj | B8: Banaszkiewicz | C8: =A8&" "&B8 -> Mikołaj Banaszkiewicz | D8: =VLOOKUP(C8,CAPACITY!$C$12:$E$69,2,0) -> BE Developer | E8: =VLOOKUP(C8,CAPACITY!$C$12:$E$69,3,0) -> ALF | BI8: 0 | BJ8: 0 | BK8: 0 | BL8: 0 | BM8: 0 | BN8: 0 | BO8: 0 | BP8: 0 | BQ8: 0 | BR8: 0 | BS8: 0 | BT8: 0 | BU8: 0 | BV8: 0 | BW8: 0 | BX8: =SUM(BX9:BX11) -> 0 | BY8: =SUM(BY9:BY11) -> 0 | BZ8: 0 | CA8: 0 | CB8: 0 | CC8: 0 | CD8: 0 | CE8: 0 | CF8: 0
A9: Mikołaj | B9: Banaszkiewicz | C9: =A9&" "&B9 -> Mikołaj Banaszkiewicz | D9: =VLOOKUP(C9,CAPACITY!$C$12:$E$69,2,0) -> BE Developer | E9: =VLOOKUP(C9,CAPACITY!$C$12:$E$69,3,0) -> ALF | BI9: 0 | BJ9: 0 | BK9: 0 | BL9: 0 | BM9: 0 | BN9: 0 | BO9: 0 | BP9: 0 | BQ9: 0 | BR9: 0 | BS9: 0 | BT9: 0 | BU9: 0 | BV9: 0 | BW9: 0 | BX9: =SUM(BX10:BX12) -> 0 | BY9: =SUM(BY10:BY12) -> 0 | BZ9: 0 | CA9: 0 | CB9: 0 | CC9: 0 | CD9: 0 | CE9: 0 | CF9: 0
A10: Michał | B10: Godziszewski | C10: =A10&" "&B10 -> Michał Godziszewski | D10: =VLOOKUP(C10,CAPACITY!$C$12:$E$69,2,0) -> FE Developer | E10: =VLOOKUP(C10,CAPACITY!$C$12:$E$69,3,0) -> ALF | BI10: =SUM(BI11:BI13) -> 0 | BJ10: =SUM(BJ11:BJ13) -> 0 | BK10: =SUM(BK11:BK13) -> 0 | BL10: =SUM(BL11:BL13) -> 0 | BM10: =SUM(BM11:BM13) -> 0 | BN10: =SUM(BN11:BN13) -> 0 | BO10: =SUM(BO11:BO13) -> 0 | BP10: =SUM(BP11:BP13) -> 0 | ... CF10: =SUM(CF11:CF13) -> 0
A11: Michał | B11: Godziszewski | C11: =A11&" "&B11 -> Michał Godziszewski | D11: =VLOOKUP(C11,CAPACITY!$C$12:$E$69,2,0) -> FE Developer | E11: =VLOOKUP(C11,CAPACITY!$C$12:$E$69,3,0) -> ALF | F11: JET | BI11: 0 | BJ11: 0 | BK11: 0 | BL11: 0 | BM11: 0 | BN11: 0 | BO11: 0 | BP11: 0 | BQ11: 0 | BR11: 0 | BS11: 1 | BT11: 1 | BU11: 1 | BV11: 1 | BW11: 1 | BX11: =SUM(BX12:BX14) -> 0 | BY11: =SUM(BY12:BY14) -> 0 | BZ11: 1 | CA11: 1 | CB11: 1 | CC11: 1 | CD11: 1 | CE11: 0 | CF11: 0
A12: Michał | B12: Godziszewski | C12: =A12&" "&B12 -> Michał Godziszewski | D12: =VLOOKUP(C12,CAPACITY!$C$12:$E$69,2,0) -> FE Developer | E12: =VLOOKUP(C12,CAPACITY!$C$12:$E$69,3,0) -> ALF | BI12: 0 | BJ12: 0 | BK12: 0 | BL12: 0 | BM12: 0 | BN12: 0 | BO12: 0 | BP12: 0 | BQ12: 0 | BR12: 0 | BS12: 0 | BT12: 0 | BU12: 0 | BV12: 0 | BW12: 0 | BX12: =SUM(BX13:BX15) -> 0 | BY12: =SUM(BY13:BY15) -> 0 | BZ12: 0 | CA12: 0 | CB12: 0 | CC12: 0 | CD12: 0 | CE12: 0 | CF12: 0
A13: Michał | B13: Godziszewski | C13: =A13&" "&B13 -> Michał Godziszewski | D13: =VLOOKUP(C13,CAPACITY!$C$12:$E$69,2,0) -> FE Developer | E13: =VLOOKUP(C13,CAPACITY!$C$12:$E$69,3,0) -> ALF | BI13: 0 | BJ13: 0 | BK13: 0 | BL13: 0 | BM13: 0 | BN13: 0 | BO13: 0 | BP13: 0 | BQ13: 0 | BR13: 0 | BS13: 0 | BT13: 0 | BU13: 0 | BV13: 0 | BW13: 0 | BX13: =SUM(BX14:BX16) -> 0 | BY13: =SUM(BY14:BY16) -> 0 | BZ13: 0 | CA13: 0 | CB13: 0 | CC13: 0 | CD13: 0 | CE13: 0 | CF13: 0
A14: Adam | B14: Gruszecki | C14: =A14&" "&B14 -> Adam Gruszecki | D14: =VLOOKUP(C14,CAPACITY!$C$12:$E$69,2,0) -> BE Developer | E14: =VLOOKUP(C14,CAPACITY!$C$12:$E$69,3,0) -> ALF | BI14: =SUM(BI15:BI17) -> 0 | BJ14: =SUM(BJ15:BJ17) -> 0 | BK14: =SUM(BK15:BK17) -> 0 | BL14: =SUM(BL15:BL17) -> 0 | BM14: =SUM(BM15:BM17) -> 0 | BN14: =SUM(BN15:BN17) -> 0 | BO14: =SUM(BO15:BO17) -> 0 | BP14: =SUM(BP15:BP17) -> 0 | ... CF14: =SUM(CF15:CF17) -> 0
A15: Adam | B15: Gruszecki | C15: =A15&" "&B15 -> Adam Gruszecki | D15: =VLOOKUP(C15,CAPACITY!$C$12:$E$69,2,0) -> BE Developer | E15: =VLOOKUP(C15,CAPACITY!$C$12:$E$69,3,0) -> ALF | BI15: 0 | BJ15: 0 | BK15: 0 | BL15: 0 | BM15: 0 | BN15: 0 | BO15: 0 | BP15: 0 | BQ15: 0 | BR15: 0 | BS15: 0 | BT15: 0 | BU15: 0 | BV15: 0 | BW15: 0 | BX15: =SUM(BX16:BX18) -> 0 | BY15: =SUM(BY16:BY18) -> 0 | BZ15: 0 | CA15: 0 | CB15: 0 | CC15: 0 | CD15: 0 | CE15: 0 | CF15: 0
A16: Adam | B16: Gruszecki | C16: =A16&" "&B16 -> Adam Gruszecki | D16: =VLOOKUP(C16,CAPACITY!$C$12:$E$69,2,0) -> BE Developer | E16: =VLOOKUP(C16,CAPACITY!$C$12:$E$69,3,0) -> ALF | BI16: 0 | BJ16: 0 | BK16: 0 | BL16: 0 | BM16: 0 | BN16: 0 | BO16: 0 | BP16: 0 | BQ16: 0 | BR16: 0 | BS16: 0 | BT16: 0 | BU16: 0 | BV16: 0 | BW16: 0 | BX16: =SUM(BX17:BX19) -> 0 | BY16: =SUM(BY17:BY19) -> 0 | BZ16: 0 | CA16: 0 | CB16: 0 | CC16: 0 | CD16: 0 | CE16: 0 | CF16: 0
A17: Adam | B17: Gruszecki | C17: =A17&" "&B17 -> Adam Gruszecki | D17: =VLOOKUP(C17,CAPACITY!$C$12:$E$69,2,0) -> BE Developer | E17: =VLOOKUP(C17,CAPACITY!$C$12:$E$69,3,0) -> ALF | BI17: 0 | BJ17: 0 | BK17: 0 | BL17: 0 | BM17: 0 | BN17: 0 | BO17: 0 | BP17: 0 | BQ17: 0 | BR17: 0 | BS17: 0 | BT17: 0 | BU17: 0 | BV17: 0 | BW17: 0 | BX17: =SUM(BX18:BX20) -> 0 | BY17: =SUM(BY18:BY20) -> 0 | BZ17: 0 | CA17: 0 | CB17: 0 | CC17: 0 | CD17: 0 | CE17: 0 | CF17: 0
A18: Bartosz | B18: Listwan | C18: =A18&" "&B18 -> Bartosz Listwan | D18: =VLOOKUP(C18,CAPACITY!$C$12:$E$69,2,0) -> BE Developer | E18: =VLOOKUP(C18,CAPACITY!$C$12:$E$69,3,0) -> ALF | BI18: =SUM(BI19:BI21) -> 0 | BJ18: =SUM(BJ19:BJ21) -> 0 | BK18: =SUM(BK19:BK21) -> 0 | BL18: =SUM(BL19:BL21) -> 0 | BM18: =SUM(BM19:BM21) -> 0 | BN18: =SUM(BN19:BN21) -> 0 | BO18: =SUM(BO19:BO21) -> 0 | BP18: =SUM(BP19:BP21) -> 0 | ... CF18: =SUM(CF19:CF21) -> 0
A19: Bartosz | B19: Listwan | C19: =A19&" "&B19 -> Bartosz Listwan | D19: =VLOOKUP(C19,CAPACITY!$C$12:$E$69,2,0) -> BE Developer | E19: =VLOOKUP(C19,CAPACITY!$C$12:$E$69,3,0) -> ALF | BI19: 0 | BJ19: 0 | BK19: 0 | BL19: 0 | BM19: 0 | BN19: 0 | BO19: 0 | BP19: 0 | BQ19: 0 | BR19: 0 | BS19: 0 | BT19: 0 | BU19: 0 | BV19: 0 | BW19: 0 | BX19: =SUM(BX20:BX22) -> 0 | BY19: =SUM(BY20:BY22) -> 0 | BZ19: 0 | CA19: 0 | CB19: 0 | CC19: 0 | CD19: 0 | CE19: 0 | CF19: 0
A20: Bartosz | B20: Listwan | C20: =A20&" "&B20 -> Bartosz Listwan | D20: =VLOOKUP(C20,CAPACITY!$C$12:$E$69,2,0) -> BE Developer | E20: =VLOOKUP(C20,CAPACITY!$C$12:$E$69,3,0) -> ALF | BI20: 0 | BJ20: 0 | BK20: 0 | BL20: 0 | BM20: 0 | BN20: 0 | BO20: 0 | BP20: 0 | BQ20: 0 | BR20: 0 | BS20: 0 | BT20: 0 | BU20: 0 | BV20: 0 | BW20: 0 | BX20: =SUM(BX21:BX23) -> 0 | BY20: =SUM(BY21:BY23) -> 0 | BZ20: 0 | CA20: 0 | CB20: 0 | CC20: 0 | CD20: 0 | CE20: 0 | CF20: 0
A21: Bartosz | B21: Listwan | C21: =A21&" "&B21 -> Bartosz Listwan | D21: =VLOOKUP(C21,CAPACITY!$C$12:$E$69,2,0) -> BE Developer | E21: =VLOOKUP(C21,CAPACITY!$C$12:$E$69,3,0) -> ALF | BI21: 0 | BJ21: 0 | BK21: 0 | BL21: 0 | BM21: 0 | BN21: 0 | BO21: 0 | BP21: 0 | BQ21: 0 | BR21: 0 | BS21: 0 | BT21: 0 | BU21: 0 | BV21: 0 | BW21: 0 | BX21: =SUM(BX22:BX24) -> 0 | BY21: =SUM(BY22:BY24) -> 0 | BZ21: 0 | CA21: 0 | CB21: 0 | CC21: 0 | CD21: 0 | CE21: 0 | CF21: 0
A22: Joanna | B22: Redes | C22: =A22&" "&B22 -> Joanna Redes | D22: =VLOOKUP(C22,CAPACITY!$C$12:$E$69,2,0) -> BE Developer | E22: =VLOOKUP(C22,CAPACITY!$C$12:$E$69,3,0) -> ALF | BI22: =SUM(BI23:BI25) -> 0 | BJ22: =SUM(BJ23:BJ25) -> 0 | BK22: =SUM(BK23:BK25) -> 0 | BL22: =SUM(BL23:BL25) -> 0 | BM22: =SUM(BM23:BM25) -> 0 | BN22: =SUM(BN23:BN25) -> 0 | BO22: =SUM(BO23:BO25) -> 0 | BP22: =SUM(BP23:BP25) -> 0 | ... CF22: =SUM(CF23:CF25) -> 0
A23: Vacancy | B23: Vacancy | C23: =A23&" "&B23 -> Vacancy Vacancy | D23: =VLOOKUP(C23,CAPACITY!$C$12:$E$69,2,0) -> #N/A | E23: =VLOOKUP(C23,CAPACITY!$C$12:$E$69,3,0) -> #N/A | BI23: 0 | BJ23: 0 | BK23: 0 | BL23: 0 | BM23: 0 | BN23: 0 | BO23: 0 | BP23: 0 | BQ23: 0 | BR23: 0 | BS23: 0 | BT23: 0 | BU23: 0 | BV23: 0 | BW23: 0 | BX23: =SUM(BX24:BX26) -> 0 | BY23: =SUM(BY24:BY26) -> 0 | BZ23: 0 | CA23: 0 | CB23: 0 | CC23: 0 | CD23: 0 | CE23: 0 | CF23: 0
A24: Daniel | B24: Martyniuk | C24: =A24&" "&B24 -> Daniel Martyniuk | D24: =VLOOKUP(C24,CAPACITY!$C$12:$E$69,2,0) -> #N/A | E24: =VLOOKUP(C24,CAPACITY!$C$12:$E$69,3,0) -> #N/A
A25: Konrad | B25: Janiak | C25: =A25&" "&B25 -> Konrad Janiak | D25: =VLOOKUP(C25,CAPACITY!$C$12:$E$69,2,0) -> #N/A | E25: =VLOOKUP(C25,CAPACITY!$C$12:$E$69,3,0) -> #N/A
A26: Tomasz | B26: Sabała | C26: =A26&" "&B26 -> Tomasz Sabała | D26: =VLOOKUP(C26,CAPACITY!$C$12:$E$69,2,0) -> BE Developer | E26: =VLOOKUP(C26,CAPACITY!$C$12:$E$69,3,0) -> MASH
A27: Adrian | B27: Słabicki | C27: =A27&" "&B27 -> Adrian Słabicki | D27: =VLOOKUP(C27,CAPACITY!$C$12:$E$69,2,0) -> BE Developer | E27: =VLOOKUP(C27,CAPACITY!$C$12:$E$69,3,0) -> ALF
A28: Szymon | B28: Bratnik | C28: =A28&" "&B28 -> Szymon Bratnik | D28: =VLOOKUP(C28,CAPACITY!$C$12:$E$69,2,0) -> #N/A | E28: =VLOOKUP(C28,CAPACITY!$C$12:$E$69,3,0) -> #N/A
A29: Żaneta | B29: Fedor-Zalewska | C29: =A29&" "&B29 -> Żaneta Fedor-Zalewska | D29: =VLOOKUP(C29,CAPACITY!$C$12:$E$69,2,0) -> QA coordinator | E29: =VLOOKUP(C29,CAPACITY!$C$12:$E$69,3,0) -> ALF
A30: Jarosław | B30: Gawroński | C30: =A30&" "&B30 -> Jarosław Gawroński | D30: =VLOOKUP(C30,CAPACITY!$C$12:$E$69,2,0) -> QAA | E30: =VLOOKUP(C30,CAPACITY!$C$12:$E$69,3,0) -> ALF
A31: Karpo | B31: Dub | C31: =A31&" "&B31 -> Karpo Dub | D31: =VLOOKUP(C31,CAPACITY!$C$12:$E$69,2,0) -> #N/A | E31: =VLOOKUP(C31,CAPACITY!$C$12:$E$69,3,0) -> #N/A
A32: Tomasz | B32: Wierachowski | C32: =A32&" "&B32 -> Tomasz Wierachowski | D32: =VLOOKUP(C32,CAPACITY!$C$12:$E$69,2,0) -> QAE | E32: =VLOOKUP(C32,CAPACITY!$C$12:$E$69,3,0) -> MASH
A33: Jarosław | B33: Gawroński | C33: =A33&" "&B33 -> Jarosław Gawroński | D33: =VLOOKUP(C33,CAPACITY!$C$12:$E$69,2,0) -> QAA | E33: =VLOOKUP(C33,CAPACITY!$C$12:$E$69,3,0) -> ALF
A34: Karpo | B34: Dub | C34: =A34&" "&B34 -> Karpo Dub | D34: =VLOOKUP(C34,CAPACITY!$C$12:$E$69,2,0) -> #N/A | E34: =VLOOKUP(C34,CAPACITY!$C$12:$E$69,3,0) -> #N/A
A35: Tomasz | B35: Wierachowski | C35: =A35&" "&B35 -> Tomasz Wierachowski | D35: =VLOOKUP(C35,CAPACITY!$C$12:$E$69,2,0) -> QAE | E35: =VLOOKUP(C35,CAPACITY!$C$12:$E$69,3,0) -> MASH
... A39: Tomasz | B39: Wierachowski | C39: =A39&" "&B39 -> Tomasz Wierachowski | D39: =VLOOKUP(C39,CAPACITY!$C$12:$E$69,2,0) -> QAE | E39: =VLOOKUP(C39,CAPACITY!$C$12:$E$69,3,0) -> MASH

Sheet WORKLOAD_TEAMS (2)
A1: PRIORYTET | B1: DATE | C1: DATE | D1: TOTALS | E1: =TEXT(DATE(2024,1,1)+(E2-1)*7-WEEKDAY(DATE(2024,1,1),2)+1,"dd.mm")&"-"&TEXT(DATE(2024,1,1)+(E2-1)*7-WEEKDAY(DATE(2024,1,1),2)+7,"dd.mm") -> 11.03-17.03 | F1: =TEXT(DATE(2024,1,1)+(F2-1)*7-WEEKDAY(DATE(2024,1,1),2)+1,"dd.mm")&"-"&TEXT(DATE(2024,1,1)+(F2-1)*7-WEEKDAY(DATE(2024,1,1),2)+7,"dd.mm") -> 18.03-24.03 | G1: =TEXT(DATE(2024,1,1)+(G2-1)*7-WEEKDAY(DATE(2024,1,1),2)+1,"dd.mm")&"-"&TEXT(DATE(2024,1,1)+(G2-1)*7-WEEKDAY(DATE(2024,1,1),2)+7,"dd.mm") -> 25.03-31.03 | H1: =TEXT(DATE(2024,1,1)+(H2-1)*7-WEEKDAY(DATE(2024,1,1),2)+1,"dd.mm")&"-"&TEXT(DATE(2024,1,1)+(H2-1)*7-WEEKDAY(DATE(2024,1,1),2)+7,"dd.mm") -> 01.04-07.04 | I1: =TEXT(DATE(2024,1,1)+(I2-1)*7-WEEKDAY(DATE(2024,1,1),2)+1,"dd.mm")&"-"&TEXT(DATE(2024,1,1)+(I2-1)*7-WEEKDAY(DATE(2024,1,1),2)+7,"dd.mm") -> 08.04-14.04 | J1: =TEXT(DATE(2024,1,1)+(J2-1)*7-WEEKDAY(DATE(2024,1,1),2)+1,"dd.mm")&"-"&TEXT(DATE(2024,1,1)+(J2-1)*7-WEEKDAY(DATE(2024,1,1),2)+7,"dd.mm") -> 15.04-21.04 | K1: =TEXT(DATE(2024,1,1)+(K2-1)*7-WEEKDAY(DATE(2024,1,1),2)+1,"dd.mm")&"-"&TEXT(DATE(2024,1,1)+(K2-1)*7-WEEKDAY(DATE(2024,1,1),2)+7,"dd.mm") -> 22.04-28.04 | L1: =TEXT(DATE(2024,1,1)+(L2-1)*7-WEEKDAY(DATE(2024,1,1),2)+1,"dd.mm")&"-"&TEXT(DATE(2024,1,1)+(L2-1)*7-WEEKDAY(DATE(2024,1,1),2)+7,"dd.mm") -> 29.04-05.05 | ... AT1: =TEXT(DATE(2024,1,1)+(AT2-1)*7-WEEKDAY(DATE(2024,1,1),2)+1,"dd.mm")&"-"&TEXT(DATE(2024,1,1)+(AT2-1)*7-WEEKDAY(DATE(2024,1,1),2)+7,"dd.mm") -> 23.12-29.12 | AU1: =TEXT(DATE(2025,1,1)+(AU2-1)*7-WEEKDAY(DATE(2025,1,1),2)+1,"dd.mm")&"-"&TEXT(DATE(2025,1,1)+(AU2-1)*7-WEEKDAY(DATE(2025,1,1),2)+7,"dd.mm") -> 30.12-05.01 | AV1: =TEXT(DATE(2025,1,1)+(AV2-1)*7-WEEKDAY(DATE(2025,1,1),2)+1,"dd.mm")&"-"&TEXT(DATE(2025,1,1)+(AV2-1)*7-WEEKDAY(DATE(2025,1,1),2)+7,"dd.mm") -> 06.01-12.01 | AW1: =TEXT(DATE(2025,1,1)+(AW2-1)*7-WEEKDAY(DATE(2025,1,1),2)+1,"dd.mm")&"-"&TEXT(DATE(2025,1,1)+(AW2-1)*7-WEEKDAY(DATE(2025,1,1),2)+7,"dd.mm") -> 13.01-19.01 | AX1: =TEXT(DATE(2025,1,1)+(AX2-1)*7-WEEKDAY(DATE(2025,1,1),2)+1,"dd.mm")&"-"&TEXT(DATE(2025,1,1)+(AX2-1)*7-WEEKDAY(DATE(2025,1,1),2)+7,"dd.mm") -> 20.01-26.01 | AY1: =TEXT(DATE(2025,1,1)+(AY2-1)*7-WEEKDAY(DATE(2025,1,1),2)+1,"dd.mm")&"-"&TEXT(DATE(2025,1,1)+(AY2-1)*7-WEEKDAY(DATE(2025,1,1),2)+7,"dd.mm") -> 27.01-02.02 | AZ1: =TEXT(DATE(2025,1,1)+(AZ2-1)*7-WEEKDAY(DATE(2025,1,1),2)+1,"dd.mm")&"-"&TEXT(DATE(2025,1,1)+(AZ2-1)*7-WEEKDAY(DATE(2025,1,1),2)+7,"dd.mm") -> 03.02-09.02 | BA1: =TEXT(DATE(2025,1,1)+(BA2-1)*7-WEEKDAY(DATE(2025,1,1),2)+1,"dd.mm")&"-"&TEXT(DATE(2025,1,1)+(BA2-1)*7-WEEKDAY(DATE(2025,1,1),2)+7,"dd.mm") -> 10.02-16.02 | BB1: =TEXT(DATE(2025,1,1)+(BB2-1)*7-WEEKDAY(DATE(2025,1,1),2)+1,"dd.mm")&"-"&TEXT(DATE(2025,1,1)+(BB2-1)*7-WEEKDAY(DATE(2025,1,1),2)+7,"dd.mm") -> 17.02-23.02 | ... CT1: =TEXT(DATE(2025,1,1)+(CT2-1)*7-WEEKDAY(DATE(2025,1,1),2)+1,"dd.mm")&"-"&TEXT(DATE(2025,1,1)+(CT2-1)*7-WEEKDAY(DATE(2025,1,1),2)+7,"dd.mm") -> 22.12-28.12
C2: WEEK | E2: 11 | F2: 12 | G2: 13 | H2: 14 | I2: 15 | J2: 16 | K2: 17 | L2: 18 | M2: 19 | N2: 20 | O2: 21 | P2: 22 | Q2: 23 | R2: 24 | S2: 25 | T2: 26 | U2: 27 | V2: 28 | W2: 29 | X2: 30 | Y2: 31 | Z2: 32 | AA2: 33 | AB2: 34 | AC2: 35 | AD2: 36 | AE2: 37 | AF2: 38 | AG2: 39 | AH2: 40 | AI2: 41 | AJ2: 42 | AK2: 43 | AL2: 44 | AM2: 45 | AN2: 46 | AO2: 47 | AP2: 48 | AQ2: 49 | AR2: 50 | AS2: 51 | AT2: 52 | AU2: 1 | AV2: 2 | AW2: 3 | AX2: 4 | AY2: 5 | AZ2: 6 | BA2: 7 | BB2: 8 | BC2: 9 | BD2: 10 | BE2: 11 | BF2: 12 | BG2: 13 | BH2: 14 | BI2: 15 | BJ2: 16 | BK2: 17 | BL2: 18 | BM2: 19 | BN2: 20 | BO2: 21 | BP2: 22 | BQ2: 23 | BR2: 24 | BS2: 25 | BT2: 26 | BU2: 27 | BV2: 28 | BW2: 29 | BX2: 30 | BY2: 31 | BZ2: 32 | CA2: 33 | CB2: 34 | CC2: 35 | CD2: 36 | CE2: 37 | CF2: 38 | CG2: 39 | CH2: 40 | CI2: 41 | CJ2: 42 | CK2: 43 | CL2: 44 | CM2: 45 | CN2: 46 | CO2: 47 | CP2: 48 | CQ2: 49 | CR2: 50 | CS2: 51 | CT2: 52
B3: PROJECTS & FUNCTIONALITIES CAPACITY | C3: ALF | E3: =CAPACITY!G2 -> 27.342 | F3: =OFFSET(CAPACITY!$G$2,0,7*(F$2-$E$2)) -> 27.342 | G3: =OFFSET(CAPACITY!$G$2,0,7*(G$2-$E$2)) -> 27.342 | H3: =OFFSET(CAPACITY!$G$2,0,7*(H$2-$E$2)) -> 21.462 | I3: =OFFSET(CAPACITY!$G$2,0,7*(I$2-$E$2)) -> 27.342 | J3: =OFFSET(CAPACITY!$G$2,0,7*(J$2-$E$2)) -> 27.342 | K3: =OFFSET(CAPACITY!$G$2,0,7*(K$2-$E$2)) -> 27.342 | L3: =OFFSET(CAPACITY!$G$2,0,7*(L$2-$E$2)) -> 14.028 | M3: =OFFSET(CAPACITY!$G$2,0,7*(M$2-$E$2)) -> 28.371 | ... AT3: =OFFSET(CAPACITY!$G$2,0,7*(AT$2-$E$2)) -> 12.39 | AU3: =OFFSET(CAPACITY!$G$2,0,7*(AU$2+52-$E$2)) -> 17.346 | AV3: =OFFSET(CAPACITY!$G$2,0,7*(AV$2+52-$E$2)) -> 23.247 | AW3: =OFFSET(CAPACITY!$G$2,0,7*(AW$2+52-$E$2)) -> 28.728 | AX3: =OFFSET(CAPACITY!$G$2,0,7*(AX$2+52-$E$2)) -> 28.728 | AY3: =OFFSET(CAPACITY!$G$2,0,7*(AY$2+52-$E$2)) -> 26.439 | AZ3: =OFFSET(CAPACITY!$G$2,0,7*(AZ$2+52-$E$2)) -> 28.455 | BA3: =OFFSET(CAPACITY!$G$2,0,7*(BA$2+52-$E$2)) -> 27.342 | BB3: =OFFSET(CAPACITY!$G$2,0,7*(BB$2+52-$E$2)) -> 28.581 | ... CT3: =OFFSET(CAPACITY!$G$2,0,7*(CT$2+52-$E$2)) -> 9.66
C4: WAREX | E4: =CAPACITY!G4 -> 10.388559 | F4: =OFFSET(CAPACITY!$G$4,0,7*(F$2-$E$2)) -> 10.388559 | G4: =OFFSET(CAPACITY!$G$4,0,7*(G$2-$E$2)) -> 10.388559 | H4: =OFFSET(CAPACITY!$G$4,0,7*(H$2-$E$2)) -> 8.1544599 | I4: =OFFSET(CAPACITY!$G$4,0,7*(I$2-$E$2)) -> 10.388559 | J4: =OFFSET(CAPACITY!$G$4,0,7*(J$2-$E$2)) -> 10.069402 | K4: =OFFSET(CAPACITY!$G$4,0,7*(K$2-$E$2)) -> 10.388559 | L4: =OFFSET(CAPACITY!$G$4,0,7*(L$2-$E$2)) -> 1.9149417 | M4: =OFFSET(CAPACITY!$G$4,0,7*(M$2-$E$2)) -> 9.4310877 | ... AT4: =OFFSET(CAPACITY!$G$4,0,7*(AT$2-$E$2)) -> 9.4151298 | AU4: =OFFSET(CAPACITY!$G$4,0,7*(AU$2+52-$E$2)) -> 13.181182 | AV4: =OFFSET(CAPACITY!$G$4,0,7*(AV$2+52-$E$2)) -> 17.665337 | AW4: =OFFSET(CAPACITY!$G$4,0,7*(AW$2+52-$E$2)) -> 21.830335 | AX4: =OFFSET(CAPACITY!$G$4,0,7*(AX$2+52-$E$2)) -> 21.830335 | AY4: =OFFSET(CAPACITY!$G$4,0,7*(AY$2+52-$E$2)) -> 20.09093 | AZ4: =OFFSET(CAPACITY!$G$4,0,7*(AZ$2+52-$E$2)) -> 21.622883 | BA4: =OFFSET(CAPACITY!$G$4,0,7*(BA$2+52-$E$2)) -> 20.777117 | BB4: =OFFSET(CAPACITY!$G$4,0,7*(BB$2+52-$E$2)) -> 21.71863 | ... CT4: =OFFSET(CAPACITY!$G$4,0,7*(CT$2+52-$E$2)) -> 7.3406097
C5: OPTIMUS | E5: =CAPACITY!G6 -> 21.241748 | F5: =OFFSET(CAPACITY!$G$6,0,7*(F$2-$E$2)) -> 21.241748 | G5: =OFFSET(CAPACITY!$G$6,0,7*(G$2-$E$2)) -> 21.241748 | H5: =OFFSET(CAPACITY!$G$6,0,7*(H$2-$E$2)) -> 16.67363 | I5: =OFFSET(CAPACITY!$G$6,0,7*(I$2-$E$2)) -> 21.241748 | J5: =OFFSET(CAPACITY!$G$6,0,7*(J$2-$E$2)) -> 21.241748 | K5: =OFFSET(CAPACITY!$G$6,0,7*(K$2-$E$2)) -> 21.241748 | L5: =OFFSET(CAPACITY!$G$6,0,7*(L$2-$E$2)) -> 8.995678 | M5: =OFFSET(CAPACITY!$G$6,0,7*(M$2-$E$2)) -> 18.395459 | ... AT5: =OFFSET(CAPACITY!$G$6,0,7*(AT$2-$E$2)) -> 7.9063577 | AU5: =OFFSET(CAPACITY!$G$6,0,7*(AU$2+52-$E$2)) -> 12.281209 | AV5: =OFFSET(CAPACITY!$G$6,0,7*(AV$2+52-$E$2)) -> 14.705825 | AW5: =OFFSET(CAPACITY!$G$6,0,7*(AW$2+52-$E$2)) -> 20.082148 | AX5: =OFFSET(CAPACITY!$G$6,0,7*(AX$2+52-$E$2)) -> 20.082148 | AY5: =OFFSET(CAPACITY!$G$6,0,7*(AY$2+52-$E$2)) -> 18.852271 | AZ5: =OFFSET(CAPACITY!$G$6,0,7*(AZ$2+52-$E$2)) -> 19.027967 | BA5: =OFFSET(CAPACITY!$G$6,0,7*(BA$2+52-$E$2)) -> 17.270999 | BB5: =OFFSET(CAPACITY!$G$6,0,7*(BB$2+52-$E$2)) -> 15.074789 | ... CT5: =OFFSET(CAPACITY!$G$6,0,7*(CT$2+52-$E$2)) -> 4.9195114
C6: MASH | E6: =CAPACITY!G8 -> 8.1375 | F6: =OFFSET(CAPACITY!$G$8,0,7*(F$2-$E$2)) -> 8.1375 | G6: =OFFSET(CAPACITY!$G$8,0,7*(G$2-$E$2)) -> 8.1375 | H6: =OFFSET(CAPACITY!$G$8,0,7*(H$2-$E$2)) -> 6.3875 | I6: =OFFSET(CAPACITY!$G$8,0,7*(I$2-$E$2)) -> 8.1375 | J6: =OFFSET(CAPACITY!$G$8,0,7*(J$2-$E$2)) -> 8.1375 | K6: =OFFSET(CAPACITY!$G$8,0,7*(K$2-$E$2)) -> 8.1375 | L6: =OFFSET(CAPACITY!$G$8,0,7*(L$2-$E$2)) -> 5.25 | M6: =OFFSET(CAPACITY!$G$8,0,7*(M$2-$E$2)) -> 8.1375 | ... AT6: =OFFSET(CAPACITY!$G$8,0,7*(AT$2-$E$2)) -> 2.205 | AU6: =OFFSET(CAPACITY!$G$8,0,7*(AU$2+52-$E$2)) -> 3.4825 | AV6: =OFFSET(CAPACITY!$G$8,0,7*(AV$2+52-$E$2)) -> 6.0375 | AW6: =OFFSET(CAPACITY!$G$8,0,7*(AW$2+52-$E$2)) -> 7.91 | AX6: =OFFSET(CAPACITY!$G$8,0,7*(AX$2+52-$E$2)) -> 7.21 | AY6: =OFFSET(CAPACITY!$G$8,0,7*(AY$2+52-$E$2)) -> 6.86 | AZ6: =OFFSET(CAPACITY!$G$8,0,7*(AZ$2+52-$E$2)) -> 6.7375 | BA6: =OFFSET(CAPACITY!$G$8,0,7*(BA$2+52-$E$2)) -> 6.16 | BB6: =OFFSET(CAPACITY!$G$8,0,7*(BB$2+52-$E$2)) -> 7.56 | ... CT6: =OFFSET(CAPACITY!$G$8,0,7*(CT$2+52-$E$2)) -> 3.15
C7: MAGENTO | E7: =CAPACITY!G10 -> 23.2875 | F7: =OFFSET(CAPACITY!$G$10,0,7*(F$2-$E$2)) -> 23.2875 | G7: =OFFSET(CAPACITY!$G$10,0,7*(G$2-$E$2)) -> 23.2875 | H7: =OFFSET(CAPACITY!$G$10,0,7*(H$2-$E$2)) -> 22.5375 | I7: =OFFSET(CAPACITY!$G$10,0,7*(I$2-$E$2)) -> 23.2875 | J7: =OFFSET(CAPACITY!$G$10,0,7*(J$2-$E$2)) -> 23.2875 | K7: =OFFSET(CAPACITY!$G$10,0,7*(K$2-$E$2)) -> 23.2875 | L7: =OFFSET(CAPACITY!$G$10,0,7*(L$2-$E$2)) -> 20.25 | M7: =OFFSET(CAPACITY!$G$10,0,7*(M$2-$E$2)) -> 24.1575 | ... AT7: =OFFSET(CAPACITY!$G$10,0,7*(AT$2-$E$2)) -> 12.1125 | AU7: =OFFSET(CAPACITY!$G$10,0,7*(AU$2+52-$E$2)) -> 15.6675 | AV7: =OFFSET(CAPACITY!$G$10,0,7*(AV$2+52-$E$2)) -> 19.18875 | AW7: =OFFSET(CAPACITY!$G$10,0,7*(AW$2+52-$E$2)) -> 24.1575 | AX7: =OFFSET(CAPACITY!$G$10,0,7*(AX$2+52-$E$2)) -> 24.1575 | AY7: =OFFSET(CAPACITY!$G$10,0,7*(AY$2+52-$E$2)) -> 24.1575 | AZ7: =OFFSET(CAPACITY!$G$10,0,7*(AZ$2+52-$E$2)) -> 24.1575 | BA7: =OFFSET(CAPACITY!$G$10,0,7*(BA$2+52-$E$2)) -> 24.1575 | BB7: =OFFSET(CAPACITY!$G$10,0,7*(BB$2+52-$E$2)) -> 24.1575 | ... CT7: =OFFSET(CAPACITY!$G$10,0,7*(CT$2+52-$E$2)) -> 7.5
B8: PROJECTS & FUNCTIONALITIES CAPACITY UTILISATION | C8: ALF | E8: =E3-SUMIF($C$13:$C$519,$C8,E13:E519) -> 15.342 | F8: =F3-SUMIF($C$13:$C$519,$C8,F13:F519) -> 15.342 | G8: =G3-SUMIF($C$13:$C$519,$C8,G13:G519) -> 15.342 | H8: =H3-SUMIF($C$13:$C$519,$C8,H13:H519) -> 9.462 | I8: =I3-SUMIF($C$13:$C$519,$C8,I13:I519) -> 15.342 | J8: =J3-SUMIF($C$13:$C$519,$C8,J13:J519) -> 15.342 | K8: =K3-SUMIF($C$13:$C$519,$C8,K13:K519) -> 5.342 | L8: =L3-SUMIF($C$13:$C$519,$C8,L13:L519) -> -3.972 | ... BI8: =BI3-SUMIF($C$13:$C$519,$C8,BI13:BI519) -> 30.702
C9: WAREX | E9: =E4-SUMIF($C$13:$C$519,$C9,E13:E519) -> 10.388559 | F9: =F4-SUMIF($C$13:$C$519,$C9,F13:F519) -> 10.388559 | G9: =G4-SUMIF($C$13:$C$519,$C9,G13:G519) -> 10.388559 | H9: =H4-SUMIF($C$13:$C$519,$C9,H13:H519) -> 0.15445992 | I9: =I4-SUMIF($C$13:$C$519,$C9,I13:I519) -> 2.3885585 | J9: =J4-SUMIF($C$13:$C$519,$C9,J13:J519) -> 2.0694016 | K9: =K4-SUMIF($C$13:$C$519,$C9,K13:K519) -> -3.6114415 | L9: =L4-SUMIF($C$13:$C$519,$C9,L13:L519) -> -4.0850583 | ... BI9: =BI4-SUMIF($C$13:$C$519,$C9,BI13:BI519) -> 23.330373
C10: OPTIMUS | E10: =E5-SUMIF($C$13:$C$519,$C10,E13:E519) -> 21.241748 | F10: =F5-SUMIF($C$13:$C$519,$C10,F13:F519) -> 21.241748 | G10: =G5-SUMIF($C$13:$C$519,$C10,G13:G519) -> 21.241748 | H10: =H5-SUMIF($C$13:$C$519,$C10,H13:H519) -> 16.67363 | I10: =I5-SUMIF($C$13:$C$519,$C10,I13:I519) -> 21.241748 | J10: =J5-SUMIF($C$13:$C$519,$C10,J13:J519) -> 21.241748 | K10: =K5-SUMIF($C$13:$C$519,$C10,K13:K519) -> 21.241748 | L10: =L5-SUMIF($C$13:$C$519,$C10,L13:L519) -> 8.995678 | ... BI10: =BI5-SUMIF($C$13:$C$519,$C10,BI13:BI519) -> 17.868368
C11: MASH | E11: =E6-SUMIF($C$13:$C$519,$C11,E13:E519) -> 7.6375 | F11: =F6-SUMIF($C$13:$C$519,$C11,F13:F519) -> 7.6375 | G11: =G6-SUMIF($C$13:$C$519,$C11,G13:G519) -> 7.6375 | H11: =H6-SUMIF($C$13:$C$519,$C11,H13:H519) -> 4.8875 | I11: =I6-SUMIF($C$13:$C$519,$C11,I13:I519) -> 5.6375 | J11: =J6-SUMIF($C$13:$C$519,$C11,J13:J519) -> 3.6375 | K11: =K6-SUMIF($C$13:$C$519,$C11,K13:K519) -> 0.6375 | L11: =L6-SUMIF($C$13:$C$519,$C11,L13:L519) -> -2.25 | ... BI11: =BI6-SUMIF($C$13:$C$519,$C11,BI13:BI519) -> 8.1375
C12: MAGENTO | E12: =E7-SUMIF($C$13:$C$519,$C12,E13:E519) -> 23.2875 | F12: =F7-SUMIF($C$13:$C$519,$C12,F13:F519) -> 23.2875 | G12: =G7-SUMIF($C$13:$C$519,$C12,G13:G519) -> 23.2875 | H12: =H7-SUMIF($C$13:$C$519,$C12,H13:H519) -> 22.5375 | I12: =I7-SUMIF($C$13:$C$519,$C12,I13:I519) -> 23.2875 | J12: =J7-SUMIF($C$13:$C$519,$C12,J13:J519) -> 11.2875 | K12: =K7-SUMIF($C$13:$C$519,$C12,K13:K519) -> 0.2875 | L12: =L7-SUMIF($C$13:$C$519,$C12,L13:L519) -> 2.25 | ... BI12: =BI7-SUMIF($C$13:$C$519,$C12,BI13:BI519) -> 24.4125
B13: DŁUG FUNKCJONALNY ALF | C13: ALF | D13: =SUM(E13:CT13) -> 612 | E13: 12 | F13: 12 | G13: 12 | H13: 12 | I13: 12 | J13: 12 | K13: 12 | L13: 12 | M13: 12 | N13: 12 | O13: 12 | P13: 12 | Q13: 12 | R13: 12 | S13: 12 | T13: 12 | U13: 12 | V13: 12 | W13: 12 | X13: 12 | Y13: 12 | Z13: 12 | AA13: 12 | AB13: 12 | AC13: 12 | AD13: 12 | AE13: 12 | AF13: 12 | AG13: 12 | AH13: 12 | AI13: 12 | AJ13: 12 | AK13: 12 | AL13: 12 | AM13: 12 | AN13: 12 | AO13: 12 | AP13: 12 | AQ13: 12 | AR13: 12 | AS13: 12 | AV13: 12 | AW13: 12 | AX13: 12 | AY13: 12 | AZ13: 12 | BA13: 12 | BB13: 12 | BC13: 12 | BD13: 12 | BE13: 12
C14: WAREX | D14: =SUM(E14:CT14) -> 0
C15: OPTIMUS | D15: =SUM(E15:CT15) -> 0
C16: MASH | D16: =SUM(E16:CT16) -> 25.5 | E16: 0.5 | F16: 0.5 | G16: 0.5 | H16: 0.5 | I16: 0.5 | J16: 0.5 | K16: 0.5 | L16: 0.5 | M16: 0.5 | N16: 0.5 | O16: 0.5 | P16: 0.5 | Q16: 0.5 | R16: 0.5 | S16: 0.5 | T16: 0.5 | U16: 0.5 | V16: 0.5 | W16: 0.5 | X16: 0.5 | Y16: 0.5 | Z16: 0.5 | AA16: 0.5 | AB16: 0.5 | AC16: 0.5 | AD16: 0.5 | AE16: 0.5 | AF16: 0.5 | AG16: 0.5 | AH16: 0.5 | AI16: 0.5 | AJ16: 0.5 | AK16: 0.5 | AL16: 0.5 | AM16: 0.5 | AN16: 0.5 | AO16: 0.5 | AP16: 0.5 | AQ16: 0.5 | AR16: 0.5 | AS16: 0.5 | AV16: 0.5 | AW16: 0.5 | AX16: 0.5 | AY16: 0.5 | AZ16: 0.5 | BA16: 0.5 | BB16: 0.5 | BC16: 0.5 | BD16: 0.5 | BE16: 0.5
C17: MAGENTO | D17: =SUM(E17:CT17) -> 0
A18: 0 | B18: Project - Portal B2B 1(1.5) | C18: ALF | D18: =SUM(E18:CT18) -> 2 | K18: 2
C19: WAREX | D19: =SUM(E19:CT19) -> 0
C20: OPTIMUS | D20: =SUM(E20:CT20) -> 0
C21: MASH | D21: =SUM(E21:CT21) -> 2 | J21: 1 | M21: 1
C22: MAGENTO | D22: =SUM(E22:CT22) -> 27 | J22: 6 | K22: 3 | L22: 3 | M22: 3 | N22: 2 | R22: 5 | S22: 5
A23: 0 | B23: Project - Multibrand for iMad | C23: ALF | D23: =SUM(E23:CT23) -> 2 | K23: 2
C24: WAREX | D24: =SUM(E24:CT24) -> 0
C25: OPTIMUS | D25: =SUM(E25:CT25) -> 0
C26: MASH | D26: =SUM(E26:CT26) -> 1 | K26: 1
C27: MAGENTO | D27: =SUM(E27:CT27) -> 35 | K27: 5 | L27: 5 | M27: 5 | Q27: 5 | R27: 5 | S27: 5 | T27: 5
A28: 0 | B28: Project - Malezja Faza 1A | C28: ALF | D28: =SUM(E28:CT28) -> 8.5 | K28: 1 | L28: 1 | M28: 0.5 | O28: 1 | P28: 3 | Q28: 2
C29: WAREX | D29: =SUM(E29:CT29) -> 1 | M29: 0.5 | N29: 0.5
C30: OPTIMUS | D30: =SUM(E30:CT30) -> 8 | P30: 0.5 | Q30: 0.5 | R30: 5 | S30: 2
C31: MASH | D31: =SUM(E31:CT31) -> 21 | H31: 1 | I31: 2 | J31: 3 | K31: 3 | L31: 2 | M31: 3 | N31: 1 | P31: 0.5 | Q31: 1 | R31: 0.5 | S31: 1 | T31: 2 | U31: 1
C32: MAGENTO | D32: =SUM(E32:CT32) -> 92 | J32: 6 | K32: 15 | L32: 10 | M32: 5 | N32: 15 | O32: 15 | P32: 10 | Q32: 5 | R32: 4 | S32: 4 | T32: 3
A33: 0 | B33: MM Open Days: Faza1 - 22/05 | C33: ALF | D33: =SUM(E33:CT33) -> 25 | K33: 5 | L33: 5 | M33: 5 | N33: 5 | O33: 5
C34: WAREX | D34: =SUM(E34:CT34) -> 2 | N34: 2
C35: OPTIMUS | D35: =SUM(E35:CT35) -> 0
C36: MASH | D36: =SUM(E36:CT36) -> 15 | K36: 3 | L36: 5 | M36: 3 | N36: 2 | O36: 2
C37: MAGENTO | D37: =SUM(E37:CT37) -> 10 | N37: 5 | O37: 5
A38: 0 | B38: MM Open Days: Faza2 - 03/06 | C38: ALF | D38: =SUM(E38:CT38) -> 0
C39: WAREX | D39: =SUM(E39:CT39) -> 0
C40: OPTIMUS | D40: =SUM(E40:CT40) -> 0
...

Sheet WORKLOAD_TEAMS (4)
A1: PRIORYTET | B1: DATE | C1: DATE | D1: TOTALS | E1: =TEXT(DATE(2024,1,1)+(E2-1)*7-WEEKDAY(DATE(2024,1,1),2)+1,"dd.mm")&"-"&TEXT(DATE(2024,1,1)+(E2-1)*7-WEEKDAY(DATE(2024,1,1),2)+7,"dd.mm") -> 11.03-17.03 | F1: =TEXT(DATE(2024,1,1)+(F2-1)*7-WEEKDAY(DATE(2024,1,1),2)+1,"dd.mm")&"-"&TEXT(DATE(2024,1,1)+(F2-1)*7-WEEKDAY(DATE(2024,1,1),2)+7,"dd.mm") -> 18.03-24.03 | G1: =TEXT(DATE(2024,1,1)+(G2-1)*7-WEEKDAY(DATE(2024,1,1),2)+1,"dd.mm")&"-"&TEXT(DATE(2024,1,1)+(G2-1)*7-WEEKDAY(DATE(2024,1,1),2)+7,"dd.mm") -> 25.03-31.03 | H1: =TEXT(DATE(2024,1,1)+(H2-1)*7-WEEKDAY(DATE(2024,1,1),2)+1,"dd.mm")&"-"&TEXT(DATE(2024,1,1)+(H2-1)*7-WEEKDAY(DATE(2024,1,1),2)+7,"dd.mm") -> 01.04-07.04 | I1: =TEXT(DATE(2024,1,1)+(I2-1)*7-WEEKDAY(DATE(2024,1,1),2)+1,"dd.mm")&"-"&TEXT(DATE(2024,1,1)+(I2-1)*7-WEEKDAY(DATE(2024,1,1),2)+7,"dd.mm") -> 08.04-14.04 | J1: =TEXT(DATE(2024,1,1)+(J2-1)*7-WEEKDAY(DATE(2024,1,1),2)+1,"dd.mm")&"-"&TEXT(DATE(2024,1,1)+(J2-1)*7-WEEKDAY(DATE(2024,1,1),2)+7,"dd.mm") -> 15.04-21.04 | K1: =TEXT(DATE(2024,1,1)+(K2-1)*7-WEEKDAY(DATE(2024,1,1),2)+1,"dd.mm")&"-"&TEXT(DATE(2024,1,1)+(K2-1)*7-WEEKDAY(DATE(2024,1,1),2)+7,"dd.mm") -> 22.04-28.04 | L1: =TEXT(DATE(2024,1,1)+(L2-1)*7-WEEKDAY(DATE(2024,1,1),2)+1,"dd.mm")&"-"&TEXT(DATE(2024,1,1)+(L2-1)*7-WEEKDAY(DATE(2024,1,1),2)+7,"dd.mm") -> 29.04-05.05 | ... AT1: =TEXT(DATE(2024,1,1)+(AT2-1)*7-WEEKDAY(DATE(2024,1,1),2)+1,"dd.mm")&"-"&TEXT(DATE(2024,1,1)+(AT2-1)*7-WEEKDAY(DATE(2024,1,1),2)+7,"dd.mm") -> 23.12-29.12 | AU1: =TEXT(DATE(2025,1,1)+(AU2-1)*7-WEEKDAY(DATE(2025,1,1),2)+1,"dd.mm")&"-"&TEXT(DATE(2025,1,1)+(AU2-1)*7-WEEKDAY(DATE(2025,1,1),2)+7,"dd.mm") -> 30.12-05.01 | AV1: =TEXT(DATE(2025,1,1)+(AV2-1)*7-WEEKDAY(DATE(2025,1,1),2)+1,"dd.mm")&"-"&TEXT(DATE(2025,1,1)+(AV2-1)*7-WEEKDAY(DATE(2025,1,1),2)+7,"dd.mm") -> 06.01-12.01 | AW1: =TEXT(DATE(2025,1,1)+(AW2-1)*7-WEEKDAY(DATE(2025,1,1),2)+1,"dd.mm")&"-"&TEXT(DATE(2025,1,1)+(AW2-1)*7-WEEKDAY(DATE(2025,1,1),2)+7,"dd.mm") -> 13.01-19.01 | AX1: =TEXT(DATE(2025,1,1)+(AX2-1)*7-WEEKDAY(DATE(2025,1,1),2)+1,"dd.mm")&"-"&TEXT(DATE(2025,1,1)+(AX2-1)*7-WEEKDAY(DATE(2025,1,1),2)+7,"dd.mm") -> 20.01-26.01 | AY1: =TEXT(DATE(2025,1,1)+(AY2-1)*7-WEEKDAY(DATE(2025,1,1),2)+1,"dd.mm")&"-"&TEXT(DATE(2025,1,1)+(AY2-1)*7-WEEKDAY(DATE(2025,1,1),2)+7,"dd.mm") -> 27.01-02.02 | AZ1: =TEXT(DATE(2025,1,1)+(AZ2-1)*7-WEEKDAY(DATE(2025,1,1),2)+1,"dd.mm")&"-"&TEXT(DATE(2025,1,1)+(AZ2-1)*7-WEEKDAY(DATE(2025,1,1),2)+7,"dd.mm") -> 03.02-09.02 | BA1: =TEXT(DATE(2025,1,1)+(BA2-1)*7-WEEKDAY(DATE(2025,1,1),2)+1,"dd.mm")&"-"&TEXT(DATE(2025,1,1)+(BA2-1)*7-WEEKDAY(DATE(2025,1,1),2)+7,"dd.mm") -> 10.02-16.02 | BB1: =TEXT(DATE(2025,1,1)+(BB2-1)*7-WEEKDAY(DATE(2025,1,1),2)+1,"dd.mm")&"-"&TEXT(DATE(2025,1,1)+(BB2-1)*7-WEEKDAY(DATE(2025,1,1),2)+7,"dd.mm") -> 17.02-23.02 | ... CT1: =TEXT(DATE(2025,1,1)+(CT2-1)*7-WEEKDAY(DATE(2025,1,1),2)+1,"dd.mm")&"-"&TEXT(DATE(2025,1,1)+(CT2-1)*7-WEEKDAY(DATE(2025,1,1),2)+7,"dd.mm") -> 22.12-28.12
C2: WEEK | E2: 11 | F2: 12 | G2: 13 | H2: 14 | I2: 15 | J2: 16 | K2: 17 | L2: 18 | M2: 19 | N2: 20 | O2: 21 | P2: 22 | Q2: 23 | R2: 24 | S2: 25 | T2: 26 | U2: 27 | V2: 28 | W2: 29 | X2: 30 | Y2: 31 | Z2: 32 | AA2: 33 | AB2: 34 | AC2: 35 | AD2: 36 | AE2: 37 | AF2: 38 | AG2: 39 | AH2: 40 | AI2: 41 | AJ2: 42 | AK2: 43 | AL2: 44 | AM2: 45 | AN2: 46 | AO2: 47 | AP2: 48 | AQ2: 49 | AR2: 50 | AS2: 51 | AT2: 52 | AU2: 1 | AV2: 2 | AW2: 3 | AX2: 4 | AY2: 5 | AZ2: 6 | BA2: 7 | BB2: 8 | BC2: 9 | BD2: 10 | BE2: 11 | BF2: 12 | BG2: 13 | BH2: 14 | BI2: 15 | BJ2: 16 | BK2: 17 | BL2: 18 | BM2: 19 | BN2: 20 | BO2: 21 | BP2: 22 | BQ2: 23 | BR2: 24 | BS2: 25 | BT2: 26 | BU2: 27 | BV2: 28 | BW2: 29 | BX2: 30 | BY2: 31 | BZ2: 32 | CA2: 33 | CB2: 34 | CC2: 35 | CD2: 36 | CE2: 37 | CF2: 38 | CG2: 39 | CH2: 40 | CI2: 41 | CJ2: 42 | CK2: 43 | CL2: 44 | CM2: 45 | CN2: 46 | CO2: 47 | CP2: 48 | CQ2: 49 | CR2: 50 | CS2: 51 | CT2: 52
B3: PROJECTS & FUNCTIONALITIES CAPACITY | C3: ALF | E3: =CAPACITY!G2 -> 27.342 | F3: =OFFSET(CAPACITY!$G$2,0,7*(F$2-$E$2)) -> 27.342 | G3: =OFFSET(CAPACITY!$G$2,0,7*(G$2-$E$2)) -> 27.342 | H3: =OFFSET(CAPACITY!$G$2,0,7*(H$2-$E$2)) -> 21.462 | I3: =OFFSET(CAPACITY!$G$2,0,7*(I$2-$E$2)) -> 27.342 | J3: =OFFSET(CAPACITY!$G$2,0,7*(J$2-$E$2)) -> 27.342 | K3: =OFFSET(CAPACITY!$G$2,0,7*(K$2-$E$2)) -> 27.342 | L3: =OFFSET(CAPACITY!$G$2,0,7*(L$2-$E$2)) -> 14.028 | M3: =OFFSET(CAPACITY!$G$2,0,7*(M$2-$E$2)) -> 28.371 | ... AT3: =OFFSET(CAPACITY!$G$2,0,7*(AT$2-$E$2)) -> 12.39 | AU3: =OFFSET(CAPACITY!$G$2,0,7*(AU$2+52-$E$2)) -> 17.346 | AV3: =OFFSET(CAPACITY!$G$2,0,7*(AV$2+52-$E$2)) -> 23.247 | AW3: =OFFSET(CAPACITY!$G$2,0,7*(AW$2+52-$E$2)) -> 28.728 | AX3: =OFFSET(CAPACITY!$G$2,0,7*(AX$2+52-$E$2)) -> 28.728 | AY3: =OFFSET(CAPACITY!$G$2,0,7*(AY$2+52-$E$2)) -> 26.439 | AZ3: =OFFSET(CAPACITY!$G$2,0,7*(AZ$2+52-$E$2)) -> 28.455 | BA3: =OFFSET(CAPACITY!$G$2,0,7*(BA$2+52-$E$2)) -> 27.342 | BB3: =OFFSET(CAPACITY!$G$2,0,7*(BB$2+52-$E$2)) -> 28.581 | ... CT3: =OFFSET(CAPACITY!$G$2,0,7*(CT$2+52-$E$2)) -> 9.66
